Workbook

Sheet Settings
A1: Balance Settings
A2: Yellow cells with blue text are inputs - change them and every tab recalculates. Values were copied from the Luau constants when this file was built.
A4: Setting | B4: Value | C4: Source / meaning
A5: Swing cooldown (s) | B5: 0.35 | C5: ShearData.SwingCooldown
A6: Base spawn interval (s) | B6: 1.5 | C6: FarmData.SpawnInterval
A7: Faster Respawn level | B7: 0 | C7: Your choice (0-8): upgrade level to model
A8: Seconds off per Faster Respawn level | B8: 0.1 | C8: UpgradeData.RespawnSecondsPerLevel
A9: Shear Damage level | B9: 0 | C9: Your choice (0-10): upgrade level to model
A10: Damage bonus per level | B10: 0.1 | C10: UpgradeData.ShearDamagePerLevel
A11: More Wool level | B11: 0 | C11: Your choice: upgrade level to model
A12: Wool multiplier per More Wool level | B12: 0.25 | C12: UpgradeData.MoreWoolPerLevel
A13: Sheep hit per swing (avg) | B13: 1 | C13: Assumption: 1 = one sheep at a time. Raise it to model bigger shears hitting groups
A14: LUCK_STRENGTH | B14: 0.5 | C14: SheepData.LUCK_STRENGTH
A15: MAX_REBIRTHS | B15: 25 | C15: RebirthData.MAX_REBIRTHS
A16: Rebirth COST_BASE (wool) | B16: 1500 | C16: RebirthData.COST_BASE
... A22: LUCK_MILESTONE_BONUS | B22: 2 | C22: RebirthData.LUCK_MILESTONE_BONUS
A23: Effective spawn interval (s) | B23: =MAX(Settings!$B$6-Settings!$B$8*Settings!$B$7,0.1) -> 1.5 | C23: Calculated
A24: More Wool multiplier | B24: =1+Settings!$B$12*Settings!$B$11 -> 1 | C24: Calculated
A26: Assumptions behind the wool-per-minute numbers:
A27: - The player swings non-stop with no walking time; time to shear a sheep = swings needed x cooldown / sheep hit per swing.
A28: - A sheep can't be sheared faster than the farm refills, so time per sheep is never below the effective spawn interval.
A29: - Rebirth odds use only the Luck a rebirth starts you with. Luck earned from shearing and from the Index during a run is extra.
A30: - Baby sheep share their type's odds and stats, so they're counted inside their adult type.

Sheet Shears
A1: Shears
A2: Blue = copied from ShearData.luau. Effective damage includes the Shear Damage level on the Settings tab.
A4: Shear | B4: Price (wool) | C4: Sheep sheared to unlock | D4: Base damage | E4: Range (studs) | F4: Effective damage | G4: Swings per second | H4: Damage per second | I4: Swings to shear Basic | J4: Swings to shear rarest | K4: Wool/min at Rebirth 0
A5: DefaultShear | B5: 0 | C5: 0 | D5: 20 | E5: 6 | F5: =MAX(ROUND(D5*(1+Settings!$B$10*Settings!$B$9),0),1) -> 20 | G5: =1/Settings!$B$5 -> 2.8571429 | H5: =F5*G5 -> 57.142857 | I5: =CEILING(INDEX(Sheep!$E$5:$E$23,MATCH("Basic Sheep",Sheep!$A$5:$A$23,0))/F5,1) -> 5 | J5: =CEILING(INDEX(Sheep!$E$5:$E$23,MATCH(MIN(Sheep!$H$5:$H$23),Sheep!$H$5:$H$23,0))/F5,1) -> 14 | K5: ='Wool per Minute'!B6 -> 580.73236
A6: SteelShears | B6: 300 | C6: 25 | D6: 26 | E6: 7.5 | F6: =MAX(ROUND(D6*(1+Settings!$B$10*Settings!$B$9),0),1) -> 26 | G6: =1/Settings!$B$5 -> 2.8571429 | H6: =F6*G6 -> 74.285714 | I6: =CEILING(INDEX(Sheep!$E$5:$E$23,MATCH("Basic Sheep",Sheep!$A$5:$A$23,0))/F6,1) -> 4 | J6: =CEILING(INDEX(Sheep!$E$5:$E$23,MATCH(MIN(Sheep!$H$5:$H$23),Sheep!$H$5:$H$23,0))/F6,1) -> 11 | K6: ='Wool per Minute'!C6 -> 721.45012
A7: LargeShears | B7: 1200 | C7: 100 | D7: 34 | E7: 9 | F7: =MAX(ROUND(D7*(1+Settings!$B$10*Settings!$B$9),0),1) -> 34 | G7: =1/Settings!$B$5 -> 2.8571429 | H7: =F7*G7 -> 97.142857 | I7: =CEILING(INDEX(Sheep!$E$5:$E$23,MATCH("Basic Sheep",Sheep!$A$5:$A$23,0))/F7,1) -> 3 | J7: =CEILING(INDEX(Sheep!$E$5:$E$23,MATCH(MIN(Sheep!$H$5:$H$23),Sheep!$H$5:$H$23,0))/F7,1) -> 8 | K7: ='Wool per Minute'!D6 -> 787.46506
A8: ElectricShears | B8: 4000 | C8: 300 | D8: 45 | E8: 11 | F8: =MAX(ROUND(D8*(1+Settings!$B$10*Settings!$B$9),0),1) -> 45 | G8: =1/Settings!$B$5 -> 2.8571429 | H8: =F8*G8 -> 128.57143 | I8: =CEILING(INDEX(Sheep!$E$5:$E$23,MATCH("Basic Sheep",Sheep!$A$5:$A$23,0))/F8,1) -> 3 | J8: =CEILING(INDEX(Sheep!$E$5:$E$23,MATCH(MIN(Sheep!$H$5:$H$23),Sheep!$H$5:$H$23,0))/F8,1) -> 6 | K8: ='Wool per Minute'!E6 -> 787.46506
A9: MasterShears | B9: 12000 | C9: 750 | D9: 60 | E9: 13 | F9: =MAX(ROUND(D9*(1+Settings!$B$10*Settings!$B$9),0),1) -> 60 | G9: =1/Settings!$B$5 -> 2.8571429 | H9: =F9*G9 -> 171.42857 | I9: =CEILING(INDEX(Sheep!$E$5:$E$23,MATCH("Basic Sheep",Sheep!$A$5:$A$23,0))/F9,1) -> 2 | J9: =CEILING(INDEX(Sheep!$E$5:$E$23,MATCH(MIN(Sheep!$H$5:$H$23),Sheep!$H$5:$H$23,0))/F9,1) -> 5 | K9: ='Wool per Minute'!F6 -> 787.46506

Sheet Sheep
A1: Sheep
A2: Blue = copied from SheepData.luau. Change a chance here to test new odds, then copy the final number back into the Luau file.
A4: Sheep | B4: Key | C4: Rarity | D4: Tier | E4: Shear Health | F4: Wool Amount | G4: Luck Amount | H4: Chance (weight) | I4: Base odds (no Luck) | J4: Base % | K4: Wool per health
A5: Basic Sheep | B5: Basic | C5: Common | D5: =MATCH(C5,Rarities!$A$5:$A$10,0)-1 -> 0 | E5: 100 | F5: 15 | G5: 1 | H5: 500000 | I5: =SUM($H$5:$H$23)/H5 -> 2.11058 | J5: =H5/SUM($H$5:$H$23) -> 0.47380341 | K5: =F5/E5 -> 0.15
A6: Grey Sheep | B6: Grey | C6: Common | D6: =MATCH(C6,Rarities!$A$5:$A$10,0)-1 -> 0 | E6: 105 | F6: 18 | G6: 1 | H6: 250000 | I6: =SUM($H$5:$H$23)/H6 -> 4.22116 | J6: =H6/SUM($H$5:$H$23) -> 0.2369017 | K6: =F6/E6 -> 0.17142857
A7: Brown Sheep | B7: Brown | C7: Uncommon | D7: =MATCH(C7,Rarities!$A$5:$A$10,0)-1 -> 1 | E7: 115 | F7: 20 | G7: 2 | H7: 150000 | I7: =SUM($H$5:$H$23)/H7 -> 7.0352667 | J7: =H7/SUM($H$5:$H$23) -> 0.14214102 | K7: =F7/E7 -> 0.17391304
A8: Black Sheep | B8: Black | C8: Uncommon | D8: =MATCH(C8,Rarities!$A$5:$A$10,0)-1 -> 1 | E8: 130 | F8: 28 | G8: 3 | H8: 60000 | I8: =SUM($H$5:$H$23)/H8 -> 17.588167 | J8: =H8/SUM($H$5:$H$23) -> 0.056856409 | K8: =F8/E8 -> 0.21538462
A9: Fluffy Sheep | B9: Fluffy | C9: Rare | D9: =MATCH(C9,Rarities!$A$5:$A$10,0)-1 -> 2 | E9: 145 | F9: 35 | G9: 5 | H9: 30000 | I9: =SUM($H$5:$H$23)/H9 -> 35.176333 | J9: =H9/SUM($H$5:$H$23) -> 0.028428205 | K9: =F9/E9 -> 0.24137931
A10: Cotton Candy Sheep | B10: CottonCandy | C10: Rare | D10: =MATCH(C10,Rarities!$A$5:$A$10,0)-1 -> 2 | E10: 155 | F10: 38 | G10: 6 | H10: 22000 | I10: =SUM($H$5:$H$23)/H10 -> 47.967727 | J10: =H10/SUM($H$5:$H$23) -> 0.02084735 | K10: =F10/E10 -> 0.24516129
A11: Ice Sheep | B11: Ice | C11: Rare | D11: =MATCH(C11,Rarities!$A$5:$A$10,0)-1 -> 2 | E11: 160 | F11: 42 | G11: 7 | H11: 20000 | I11: =SUM($H$5:$H$23)/H11 -> 52.7645 | J11: =H11/SUM($H$5:$H$23) -> 0.018952136 | K11: =F11/E11 -> 0.2625
A12: Golden Sheep | B12: Golden | C12: Epic | D12: =MATCH(C12,Rarities!$A$5:$A$10,0)-1 -> 3 | E12: 175 | F12: 50 | G12: 10 | H12: 7500 | I12: =SUM($H$5:$H$23)/H12 -> 140.70533 | J12: =H12/SUM($H$5:$H$23) -> 0.0071070511 | K12: =F12/E12 -> 0.28571429
A13: Stone Sheep | B13: Stone | C13: Epic | D13: =MATCH(C13,Rarities!$A$5:$A$10,0)-1 -> 3 | E13: 225 | F13: 32 | G13: 2 | H13: 5050 | I13: =SUM($H$5:$H$23)/H13 -> 208.96832 | J13: =H13/SUM($H$5:$H$23) -> 0.0047854144 | K13: =F13/E13 -> 0.14222222
A14: Mummy Sheep | B14: Mummy | C14: Epic | D14: =MATCH(C14,Rarities!$A$5:$A$10,0)-1 -> 3 | E14: 185 | F14: 55 | G14: 11 | H14: 5000 | I14: =SUM($H$5:$H$23)/H14 -> 211.058 | J14: =H14/SUM($H$5:$H$23) -> 0.0047380341 | K14: =F14/E14 -> 0.2972973
A15: Luck Sheep | B15: Lucky | C15: Epic | D15: =MATCH(C15,Rarities!$A$5:$A$10,0)-1 -> 3 | E15: 200 | F15: 150 | G15: 125 | H15: 2100 | I15: =SUM($H$5:$H$23)/H15 -> 502.51905 | J15: =H15/SUM($H$5:$H$23) -> 0.0019899743 | K15: =F15/E15 -> 0.75
A16: Emerald Sheep | B16: Emerald | C16: Epic | D16: =MATCH(C16,Rarities!$A$5:$A$10,0)-1 -> 3 | E16: 190 | F16: 60 | G16: 12 | H16: 2000 | I16: =SUM($H$5:$H$23)/H16 -> 527.645 | J16: =H16/SUM($H$5:$H$23) -> 0.0018952136 | K16: =F16/E16 -> 0.31578947
... A23: Obsidian Sheep | B23: Obsidian | C23: Mythic | D23: =MATCH(C23,Rarities!$A$5:$A$10,0)-1 -> 5 | E23: 270 | F23: 120 | G23: 80 | H23: 60 | I23: =SUM($H$5:$H$23)/H23 -> 17588.167 | J23: =H23/SUM($H$5:$H$23) -> 5.6856409e-05 | K23: =F23/E23 -> 0.44444444
A24: Total | H24: =SUM(H5:H23) -> 1055290 | J24: =SUM(J5:J23) -> 1

Sheet Rarities
A1: Rarities
A2: Weight band of each tier. Keep a sheep's chance inside its tier's band and it won't feel out of place.
A4: Rarity | B4: Tier (Luck power) | C4: Sheep in tier | D4: Min weight | E4: Max weight | F4: Total weight | G4: Odds of any sheep in tier | H4: Odds of commonest in tier | I4: Odds of rarest in tier
A5: Common | B5: 0 | C5: =COUNTIF(Sheep!$C$5:$C$23,A5) -> 2 | D5: =IF(C5=0,"-",_xlfn.MINIFS(Sheep!$H$5:$H$23,Sheep!$C$5:$C$23,A5)) -> 250000 | E5: =IF(C5=0,"-",_xlfn.MAXIFS(Sheep!$H$5:$H$23,Sheep!$C$5:$C$23,A5)) -> 500000 | F5: =SUMIF(Sheep!$C$5:$C$23,A5,Sheep!$H$5:$H$23) -> 750000 | G5: =IF(F5=0,"-",Sheep!$H$24/F5) -> 1.4070533 | H5: =IF(C5=0,"-",Sheep!$H$24/E5) -> 2.11058 | I5: =IF(C5=0,"-",Sheep!$H$24/D5) -> 4.22116
A6: Uncommon | B6: 1 | C6: =COUNTIF(Sheep!$C$5:$C$23,A6) -> 2 | D6: =IF(C6=0,"-",_xlfn.MINIFS(Sheep!$H$5:$H$23,Sheep!$C$5:$C$23,A6)) -> 60000 | E6: =IF(C6=0,"-",_xlfn.MAXIFS(Sheep!$H$5:$H$23,Sheep!$C$5:$C$23,A6)) -> 150000 | F6: =SUMIF(Sheep!$C$5:$C$23,A6,Sheep!$H$5:$H$23) -> 210000 | G6: =IF(F6=0,"-",Sheep!$H$24/F6) -> 5.0251905 | H6: =IF(C6=0,"-",Sheep!$H$24/E6) -> 7.0352667 | I6: =IF(C6=0,"-",Sheep!$H$24/D6) -> 17.588167
A7: Rare | B7: 2 | C7: =COUNTIF(Sheep!$C$5:$C$23,A7) -> 3 | D7: =IF(C7=0,"-",_xlfn.MINIFS(Sheep!$H$5:$H$23,Sheep!$C$5:$C$23,A7)) -> 20000 | E7: =IF(C7=0,"-",_xlfn.MAXIFS(Sheep!$H$5:$H$23,Sheep!$C$5:$C$23,A7)) -> 30000 | F7: =SUMIF(Sheep!$C$5:$C$23,A7,Sheep!$H$5:$H$23) -> 72000 | G7: =IF(F7=0,"-",Sheep!$H$24/F7) -> 14.656806 | H7: =IF(C7=0,"-",Sheep!$H$24/E7) -> 35.176333 | I7: =IF(C7=0,"-",Sheep!$H$24/D7) -> 52.7645
A8: Epic | B8: 3 | C8: =COUNTIF(Sheep!$C$5:$C$23,A8) -> 5 | D8: =IF(C8=0,"-",_xlfn.MINIFS(Sheep!$H$5:$H$23,Sheep!$C$5:$C$23,A8)) -> 2000 | E8: =IF(C8=0,"-",_xlfn.MAXIFS(Sheep!$H$5:$H$23,Sheep!$C$5:$C$23,A8)) -> 7500 | F8: =SUMIF(Sheep!$C$5:$C$23,A8,Sheep!$H$5:$H$23) -> 21650 | G8: =IF(F8=0,"-",Sheep!$H$24/F8) -> 48.743187 | H8: =IF(C8=0,"-",Sheep!$H$24/E8) -> 140.70533 | I8: =IF(C8=0,"-",Sheep!$H$24/D8) -> 527.645
A9: Legendary | B9: 4 | C9: =COUNTIF(Sheep!$C$5:$C$23,A9) -> 4 | D9: =IF(C9=0,"-",_xlfn.MINIFS(Sheep!$H$5:$H$23,Sheep!$C$5:$C$23,A9)) -> 200 | E9: =IF(C9=0,"-",_xlfn.MAXIFS(Sheep!$H$5:$H$23,Sheep!$C$5:$C$23,A9)) -> 500 | F9: =SUMIF(Sheep!$C$5:$C$23,A9,Sheep!$H$5:$H$23) -> 1400 | G9: =IF(F9=0,"-",Sheep!$H$24/F9) -> 753.77857 | H9: =IF(C9=0,"-",Sheep!$H$24/E9) -> 2110.58 | I9: =IF(C9=0,"-",Sheep!$H$24/D9) -> 5276.45
A10: Mythic | B10: 5 | C10: =COUNTIF(Sheep!$C$5:$C$23,A10) -> 3 | D10: =IF(C10=0,"-",_xlfn.MINIFS(Sheep!$H$5:$H$23,Sheep!$C$5:$C$23,A10)) -> 60 | E10: =IF(C10=0,"-",_xlfn.MAXIFS(Sheep!$H$5:$H$23,Sheep!$C$5:$C$23,A10)) -> 100 | F10: =SUMIF(Sheep!$C$5:$C$23,A10,Sheep!$H$5:$H$23) -> 240 | G10: =IF(F10=0,"-",Sheep!$H$24/F10) -> 4397.0417 | H10: =IF(C10=0,"-",Sheep!$H$24/E10) -> 10552.9 | I10: =IF(C10=0,"-",Sheep!$H$24/D10) -> 17588.167
A12: Tier is the power Luck is raised to: a sheep's weight is multiplied by luckFactor ^ tier, so Mythics gain the most from Luck.

Sheet Wool per Minute
A1: Wool per Minute
A2: Expected wool a minute for each shear at each rebirth, using the upgrade levels and assumptions on the Settings tab.
A5: Rebirths | B5: DefaultShear | C5: SteelShears | D5: LargeShears | E5: ElectricShears | F5: MasterShears
A6: 0 | B6: =60*INDEX(Rebirths!$C$6:$C$31,$A6+1)*Settings!$B$24*SUMPRODUCT(Sheep!$F$5:$F$23/INDEX('Rebirth Odds'!$C$9:$AB$27,0,$A6+1))/MAX(SUMPRODUCT(B$35:B$53/INDEX('Rebirth Odds'!$C$9:$AB$27,0,$A6+1)),Settings!$B$23) -> 580.73236 | C6: =60*INDEX(Rebirths!$C$6:$C$31,$A6+1)*Settings!$B$24*SUMPRODUCT(Sheep!$F$5:$F$23/INDEX('Rebirth Odds'!$C$9:$AB$27,0,$A6+1))/MAX(SUMPRODUCT(C$35:C$53/INDEX('Rebirth Odds'!$C$9:$AB$27,0,$A6+1)),Settings!$B$23) -> 721.45012 | D6: =60*INDEX(Rebirths!$C$6:$C$31,$A6+1)*Settings!$B$24*SUMPRODUCT(Sheep!$F$5:$F$23/INDEX('Rebirth Odds'!$C$9:$AB$27,0,$A6+1))/MAX(SUMPRODUCT(D$35:D$53/INDEX('Rebirth Odds'!$C$9:$AB$27,0,$A6+1)),Settings!$B$23) -> 787.46506 | E6: =60*INDEX(Rebirths!$C$6:$C$31,$A6+1)*Settings!$B$24*SUMPRODUCT(Sheep!$F$5:$F$23/INDEX('Rebirth Odds'!$C$9:$AB$27,0,$A6+1))/MAX(SUMPRODUCT(E$35:E$53/INDEX('Rebirth Odds'!$C$9:$AB$27,0,$A6+1)),Settings!$B$23) -> 787.46506 | F6: =60*INDEX(Rebirths!$C$6:$C$31,$A6+1)*Settings!$B$24*SUMPRODUCT(Sheep!$F$5:$F$23/INDEX('Rebirth Odds'!$C$9:$AB$27,0,$A6+1))/MAX(SUMPRODUCT(F$35:F$53/INDEX('Rebirth Odds'!$C$9:$AB$27,0,$A6+1)),Settings!$B$23) -> 787.46506
A7: 1 | B7: =60*INDEX(Rebirths!$C$6:$C$31,$A7+1)*Settings!$B$24*SUMPRODUCT(Sheep!$F$5:$F$23/INDEX('Rebirth Odds'!$C$9:$AB$27,0,$A7+1))/MAX(SUMPRODUCT(B$35:B$53/INDEX('Rebirth Odds'!$C$9:$AB$27,0,$A7+1)),Settings!$B$23) -> 1014.4249 | C7: =60*INDEX(Rebirths!$C$6:$C$31,$A7+1)*Settings!$B$24*SUMPRODUCT(Sheep!$F$5:$F$23/INDEX('Rebirth Odds'!$C$9:$AB$27,0,$A7+1))/MAX(SUMPRODUCT(C$35:C$53/INDEX('Rebirth Odds'!$C$9:$AB$27,0,$A7+1)),Settings!$B$23) -> 1271.9278 | D7: =60*INDEX(Rebirths!$C$6:$C$31,$A7+1)*Settings!$B$24*SUMPRODUCT(Sheep!$F$5:$F$23/INDEX('Rebirth Odds'!$C$9:$AB$27,0,$A7+1))/MAX(SUMPRODUCT(D$35:D$53/INDEX('Rebirth Odds'!$C$9:$AB$27,0,$A7+1)),Settings!$B$23) -> 1540.0865 | E7: =60*INDEX(Rebirths!$C$6:$C$31,$A7+1)*Settings!$B$24*SUMPRODUCT(Sheep!$F$5:$F$23/INDEX('Rebirth Odds'!$C$9:$AB$27,0,$A7+1))/MAX(SUMPRODUCT(E$35:E$53/INDEX('Rebirth Odds'!$C$9:$AB$27,0,$A7+1)),Settings!$B$23) -> 1540.0865 | F7: =60*INDEX(Rebirths!$C$6:$C$31,$A7+1)*Settings!$B$24*SUMPRODUCT(Sheep!$F$5:$F$23/INDEX('Rebirth Odds'!$C$9:$AB$27,0,$A7+1))/MAX(SUMPRODUCT(F$35:F$53/INDEX('Rebirth Odds'!$C$9:$AB$27,0,$A7+1)),Settings!$B$23) -> 1540.0865
A8: 2 | B8: =60*INDEX(Rebirths!$C$6:$C$31,$A8+1)*Settings!$B$24*SUMPRODUCT(Sheep!$F$5:$F$23/INDEX('Rebirth Odds'!$C$9:$AB$27,0,$A8+1))/MAX(SUMPRODUCT(B$35:B$53/INDEX('Rebirth Odds'!$C$9:$AB$27,0,$A8+1)),Settings!$B$23) -> 1572.0481 | C8: =60*INDEX(Rebirths!$C$6:$C$31,$A8+1)*Settings!$B$24*SUMPRODUCT(Sheep!$F$5:$F$23/INDEX('Rebirth Odds'!$C$9:$AB$27,0,$A8+1))/MAX(SUMPRODUCT(C$35:C$53/INDEX('Rebirth Odds'!$C$9:$AB$27,0,$A8+1)),Settings!$B$23) -> 1974.7754 | D8: =60*INDEX(Rebirths!$C$6:$C$31,$A8+1)*Settings!$B$24*SUMPRODUCT(Sheep!$F$5:$F$23/INDEX('Rebirth Odds'!$C$9:$AB$27,0,$A8+1))/MAX(SUMPRODUCT(D$35:D$53/INDEX('Rebirth Odds'!$C$9:$AB$27,0,$A8+1)),Settings!$B$23) -> 2450.2332 | E8: =60*INDEX(Rebirths!$C$6:$C$31,$A8+1)*Settings!$B$24*SUMPRODUCT(Sheep!$F$5:$F$23/INDEX('Rebirth Odds'!$C$9:$AB$27,0,$A8+1))/MAX(SUMPRODUCT(E$35:E$53/INDEX('Rebirth Odds'!$C$9:$AB$27,0,$A8+1)),Settings!$B$23) -> 2450.2332 | F8: =60*INDEX(Rebirths!$C$6:$C$31,$A8+1)*Settings!$B$24*SUMPRODUCT(Sheep!$F$5:$F$23/INDEX('Rebirth Odds'!$C$9:$AB$27,0,$A8+1))/MAX(SUMPRODUCT(F$35:F$53/INDEX('Rebirth Odds'!$C$9:$AB$27,0,$A8+1)),Settings!$B$23) -> 2450.2332
A9: 3 | B9: =60*INDEX(Rebirths!$C$6:$C$31,$A9+1)*Settings!$B$24*SUMPRODUCT(Sheep!$F$5:$F$23/INDEX('Rebirth Odds'!$C$9:$AB$27,0,$A9+1))/MAX(SUMPRODUCT(B$35:B$53/INDEX('Rebirth Odds'!$C$9:$AB$27,0,$A9+1)),Settings!$B$23) -> 2410.5082 | C9: =60*INDEX(Rebirths!$C$6:$C$31,$A9+1)*Settings!$B$24*SUMPRODUCT(Sheep!$F$5:$F$23/INDEX('Rebirth Odds'!$C$9:$AB$27,0,$A9+1))/MAX(SUMPRODUCT(C$35:C$53/INDEX('Rebirth Odds'!$C$9:$AB$27,0,$A9+1)),Settings!$B$23) -> 3031.7813 | D9: =60*INDEX(Rebirths!$C$6:$C$31,$A9+1)*Settings!$B$24*SUMPRODUCT(Sheep!$F$5:$F$23/INDEX('Rebirth Odds'!$C$9:$AB$27,0,$A9+1))/MAX(SUMPRODUCT(D$35:D$53/INDEX('Rebirth Odds'!$C$9:$AB$27,0,$A9+1)),Settings!$B$23) -> 3826.088 | E9: =60*INDEX(Rebirths!$C$6:$C$31,$A9+1)*Settings!$B$24*SUMPRODUCT(Sheep!$F$5:$F$23/INDEX('Rebirth Odds'!$C$9:$AB$27,0,$A9+1))/MAX(SUMPRODUCT(E$35:E$53/INDEX('Rebirth Odds'!$C$9:$AB$27,0,$A9+1)),Settings!$B$23) -> 3826.088 | F9: =60*INDEX(Rebirths!$C$6:$C$31,$A9+1)*Settings!$B$24*SUMPRODUCT(Sheep!$F$5:$F$23/INDEX('Rebirth Odds'!$C$9:$AB$27,0,$A9+1))/MAX(SUMPRODUCT(F$35:F$53/INDEX('Rebirth Odds'!$C$9:$AB$27,0,$A9+1)),Settings!$B$23) -> 3826.088
A10: 4 | B10: =60*INDEX(Rebirths!$C$6:$C$31,$A10+1)*Settings!$B$24*SUMPRODUCT(Sheep!$F$5:$F$23/INDEX('Rebirth Odds'!$C$9:$AB$27,0,$A10+1))/MAX(SUMPRODUCT(B$35:B$53/INDEX('Rebirth Odds'!$C$9:$AB$27,0,$A10+1)),Settings!$B$23) -> 3680.0335 | C10: =60*INDEX(Rebirths!$C$6:$C$31,$A10+1)*Settings!$B$24*SUMPRODUCT(Sheep!$F$5:$F$23/INDEX('Rebirth Odds'!$C$9:$AB$27,0,$A10+1))/MAX(SUMPRODUCT(C$35:C$53/INDEX('Rebirth Odds'!$C$9:$AB$27,0,$A10+1)),Settings!$B$23) -> 4633.0415 | D10: =60*INDEX(Rebirths!$C$6:$C$31,$A10+1)*Settings!$B$24*SUMPRODUCT(Sheep!$F$5:$F$23/INDEX('Rebirth Odds'!$C$9:$AB$27,0,$A10+1))/MAX(SUMPRODUCT(D$35:D$53/INDEX('Rebirth Odds'!$C$9:$AB$27,0,$A10+1)),Settings!$B$23) -> 5883.6312 | E10: =60*INDEX(Rebirths!$C$6:$C$31,$A10+1)*Settings!$B$24*SUMPRODUCT(Sheep!$F$5:$F$23/INDEX('Rebirth Odds'!$C$9:$AB$27,0,$A10+1))/MAX(SUMPRODUCT(E$35:E$53/INDEX('Rebirth Odds'!$C$9:$AB$27,0,$A10+1)),Settings!$B$23) -> 5928.5473 | F10: =60*INDEX(Rebirths!$C$6:$C$31,$A10+1)*Settings!$B$24*SUMPRODUCT(Sheep!$F$5:$F$23/INDEX('Rebirth Odds'!$C$9:$AB$27,0,$A10+1))/MAX(SUMPRODUCT(F$35:F$53/INDEX('Rebirth Odds'!$C$9:$AB$27,0,$A10+1)),Settings!$B$23) -> 5928.5473
A11: 5 | B11: =60*INDEX(Rebirths!$C$6:$C$31,$A11+1)*Settings!$B$24*SUMPRODUCT(Sheep!$F$5:$F$23/INDEX('Rebirth Odds'!$C$9:$AB$27,0,$A11+1))/MAX(SUMPRODUCT(B$35:B$53/INDEX('Rebirth Odds'!$C$9:$AB$27,0,$A11+1)),Settings!$B$23) -> 5662.9759 | C11: =60*INDEX(Rebirths!$C$6:$C$31,$A11+1)*Settings!$B$24*SUMPRODUCT(Sheep!$F$5:$F$23/INDEX('Rebirth Odds'!$C$9:$AB$27,0,$A11+1))/MAX(SUMPRODUCT(C$35:C$53/INDEX('Rebirth Odds'!$C$9:$AB$27,0,$A11+1)),Settings!$B$23) -> 7139.4873 | D11: =60*INDEX(Rebirths!$C$6:$C$31,$A11+1)*Settings!$B$24*SUMPRODUCT(Sheep!$F$5:$F$23/INDEX('Rebirth Odds'!$C$9:$AB$27,0,$A11+1))/MAX(SUMPRODUCT(D$35:D$53/INDEX('Rebirth Odds'!$C$9:$AB$27,0,$A11+1)),Settings!$B$23) -> 9059.4704 | E11: =60*INDEX(Rebirths!$C$6:$C$31,$A11+1)*Settings!$B$24*SUMPRODUCT(Sheep!$F$5:$F$23/INDEX('Rebirth Odds'!$C$9:$AB$27,0,$A11+1))/MAX(SUMPRODUCT(E$35:E$53/INDEX('Rebirth Odds'!$C$9:$AB$27,0,$A11+1)),Settings!$B$23) -> 9325.7626 | F11: =60*INDEX(Rebirths!$C$6:$C$31,$A11+1)*Settings!$B$24*SUMPRODUCT(Sheep!$F$5:$F$23/INDEX('Rebirth Odds'!$C$9:$AB$27,0,$A11+1))/MAX(SUMPRODUCT(F$35:F$53/INDEX('Rebirth Odds'!$C$9:$AB$27,0,$A11+1)),Settings!$B$23) -> 9325.7626
A12: 6 | B12: =60*INDEX(Rebirths!$C$6:$C$31,$A12+1)*Settings!$B$24*SUMPRODUCT(Sheep!$F$5:$F$23/INDEX('Rebirth Odds'!$C$9:$AB$27,0,$A12+1))/MAX(SUMPRODUCT(B$35:B$53/INDEX('Rebirth Odds'!$C$9:$AB$27,0,$A12+1)),Settings!$B$23) -> 8584.147 | C12: =60*INDEX(Rebirths!$C$6:$C$31,$A12+1)*Settings!$B$24*SUMPRODUCT(Sheep!$F$5:$F$23/INDEX('Rebirth Odds'!$C$9:$AB$27,0,$A12+1))/MAX(SUMPRODUCT(C$35:C$53/INDEX('Rebirth Odds'!$C$9:$AB$27,0,$A12+1)),Settings!$B$23) -> 10828.441 | D12: =60*INDEX(Rebirths!$C$6:$C$31,$A12+1)*Settings!$B$24*SUMPRODUCT(Sheep!$F$5:$F$23/INDEX('Rebirth Odds'!$C$9:$AB$27,0,$A12+1))/MAX(SUMPRODUCT(D$35:D$53/INDEX('Rebirth Odds'!$C$9:$AB$27,0,$A12+1)),Settings!$B$23) -> 13736.324 | E12: =60*INDEX(Rebirths!$C$6:$C$31,$A12+1)*Settings!$B$24*SUMPRODUCT(Sheep!$F$5:$F$23/INDEX('Rebirth Odds'!$C$9:$AB$27,0,$A12+1))/MAX(SUMPRODUCT(E$35:E$53/INDEX('Rebirth Odds'!$C$9:$AB$27,0,$A12+1)),Settings!$B$23) -> 14266.596 | F12: =60*INDEX(Rebirths!$C$6:$C$31,$A12+1)*Settings!$B$24*SUMPRODUCT(Sheep!$F$5:$F$23/INDEX('Rebirth Odds'!$C$9:$AB$27,0,$A12+1))/MAX(SUMPRODUCT(F$35:F$53/INDEX('Rebirth Odds'!$C$9:$AB$27,0,$A12+1)),Settings!$B$23) -> 14266.596
A13: 7 | B13: =60*INDEX(Rebirths!$C$6:$C$31,$A13+1)*Settings!$B$24*SUMPRODUCT(Sheep!$F$5:$F$23/INDEX('Rebirth Odds'!$C$9:$AB$27,0,$A13+1))/MAX(SUMPRODUCT(B$35:B$53/INDEX('Rebirth Odds'!$C$9:$AB$27,0,$A13+1)),Settings!$B$23) -> 13014.004 | C13: =60*INDEX(Rebirths!$C$6:$C$31,$A13+1)*Settings!$B$24*SUMPRODUCT(Sheep!$F$5:$F$23/INDEX('Rebirth Odds'!$C$9:$AB$27,0,$A13+1))/MAX(SUMPRODUCT(C$35:C$53/INDEX('Rebirth Odds'!$C$9:$AB$27,0,$A13+1)),Settings!$B$23) -> 16425.838 | D13: =60*INDEX(Rebirths!$C$6:$C$31,$A13+1)*Settings!$B$24*SUMPRODUCT(Sheep!$F$5:$F$23/INDEX('Rebirth Odds'!$C$9:$AB$27,0,$A13+1))/MAX(SUMPRODUCT(D$35:D$53/INDEX('Rebirth Odds'!$C$9:$AB$27,0,$A13+1)),Settings!$B$23) -> 20830.757 | E13: =60*INDEX(Rebirths!$C$6:$C$31,$A13+1)*Settings!$B$24*SUMPRODUCT(Sheep!$F$5:$F$23/INDEX('Rebirth Odds'!$C$9:$AB$27,0,$A13+1))/MAX(SUMPRODUCT(E$35:E$53/INDEX('Rebirth Odds'!$C$9:$AB$27,0,$A13+1)),Settings!$B$23) -> 21832.729 | F13: =60*INDEX(Rebirths!$C$6:$C$31,$A13+1)*Settings!$B$24*SUMPRODUCT(Sheep!$F$5:$F$23/INDEX('Rebirth Odds'!$C$9:$AB$27,0,$A13+1))/MAX(SUMPRODUCT(F$35:F$53/INDEX('Rebirth Odds'!$C$9:$AB$27,0,$A13+1)),Settings!$B$23) -> 21832.729
A14: 8 | B14: =60*INDEX(Rebirths!$C$6:$C$31,$A14+1)*Settings!$B$24*SUMPRODUCT(Sheep!$F$5:$F$23/INDEX('Rebirth Odds'!$C$9:$AB$27,0,$A14+1))/MAX(SUMPRODUCT(B$35:B$53/INDEX('Rebirth Odds'!$C$9:$AB$27,0,$A14+1)),Settings!$B$23) -> 19730.304 | C14: =60*INDEX(Rebirths!$C$6:$C$31,$A14+1)*Settings!$B$24*SUMPRODUCT(Sheep!$F$5:$F$23/INDEX('Rebirth Odds'!$C$9:$AB$27,0,$A14+1))/MAX(SUMPRODUCT(C$35:C$53/INDEX('Rebirth Odds'!$C$9:$AB$27,0,$A14+1)),Settings!$B$23) -> 24917.041 | D14: =60*INDEX(Rebirths!$C$6:$C$31,$A14+1)*Settings!$B$24*SUMPRODUCT(Sheep!$F$5:$F$23/INDEX('Rebirth Odds'!$C$9:$AB$27,0,$A14+1))/MAX(SUMPRODUCT(D$35:D$53/INDEX('Rebirth Odds'!$C$9:$AB$27,0,$A14+1)),Settings!$B$23) -> 31590.224 | E14: =60*INDEX(Rebirths!$C$6:$C$31,$A14+1)*Settings!$B$24*SUMPRODUCT(Sheep!$F$5:$F$23/INDEX('Rebirth Odds'!$C$9:$AB$27,0,$A14+1))/MAX(SUMPRODUCT(E$35:E$53/INDEX('Rebirth Odds'!$C$9:$AB$27,0,$A14+1)),Settings!$B$23) -> 33415.595 | F14: =60*INDEX(Rebirths!$C$6:$C$31,$A14+1)*Settings!$B$24*SUMPRODUCT(Sheep!$F$5:$F$23/INDEX('Rebirth Odds'!$C$9:$AB$27,0,$A14+1))/MAX(SUMPRODUCT(F$35:F$53/INDEX('Rebirth Odds'!$C$9:$AB$27,0,$A14+1)),Settings!$B$23) -> 33415.595
A15: 9 | B15: =60*INDEX(Rebirths!$C$6:$C$31,$A15+1)*Settings!$B$24*SUMPRODUCT(Sheep!$F$5:$F$23/INDEX('Rebirth Odds'!$C$9:$AB$27,0,$A15+1))/MAX(SUMPRODUCT(B$35:B$53/INDEX('Rebirth Odds'!$C$9:$AB$27,0,$A15+1)),Settings!$B$23) -> 29910.872 | C15: =60*INDEX(Rebirths!$C$6:$C$31,$A15+1)*Settings!$B$24*SUMPRODUCT(Sheep!$F$5:$F$23/INDEX('Rebirth Odds'!$C$9:$AB$27,0,$A15+1))/MAX(SUMPRODUCT(C$35:C$53/INDEX('Rebirth Odds'!$C$9:$AB$27,0,$A15+1)),Settings!$B$23) -> 37794.99 | D15: =60*INDEX(Rebirths!$C$6:$C$31,$A15+1)*Settings!$B$24*SUMPRODUCT(Sheep!$F$5:$F$23/INDEX('Rebirth Odds'!$C$9:$AB$27,0,$A15+1))/MAX(SUMPRODUCT(D$35:D$53/INDEX('Rebirth Odds'!$C$9:$AB$27,0,$A15+1)),Settings!$B$23) -> 47904.455 | E15: =60*INDEX(Rebirths!$C$6:$C$31,$A15+1)*Settings!$B$24*SUMPRODUCT(Sheep!$F$5:$F$23/INDEX('Rebirth Odds'!$C$9:$AB$27,0,$A15+1))/MAX(SUMPRODUCT(E$35:E$53/INDEX('Rebirth Odds'!$C$9:$AB$27,0,$A15+1)),Settings!$B$23) -> 51141.561 | F15: =60*INDEX(Rebirths!$C$6:$C$31,$A15+1)*Settings!$B$24*SUMPRODUCT(Sheep!$F$5:$F$23/INDEX('Rebirth Odds'!$C$9:$AB$27,0,$A15+1))/MAX(SUMPRODUCT(F$35:F$53/INDEX('Rebirth Odds'!$C$9:$AB$27,0,$A15+1)),Settings!$B$23) -> 51141.561
A16: 10 | B16: =60*INDEX(Rebirths!$C$6:$C$31,$A16+1)*Settings!$B$24*SUMPRODUCT(Sheep!$F$5:$F$23/INDEX('Rebirth Odds'!$C$9:$AB$27,0,$A16+1))/MAX(SUMPRODUCT(B$35:B$53/INDEX('Rebirth Odds'!$C$9:$AB$27,0,$A16+1)),Settings!$B$23) -> 45679.105 | C16: =60*INDEX(Rebirths!$C$6:$C$31,$A16+1)*Settings!$B$24*SUMPRODUCT(Sheep!$F$5:$F$23/INDEX('Rebirth Odds'!$C$9:$AB$27,0,$A16+1))/MAX(SUMPRODUCT(C$35:C$53/INDEX('Rebirth Odds'!$C$9:$AB$27,0,$A16+1)),Settings!$B$23) -> 57773.417 | D16: =60*INDEX(Rebirths!$C$6:$C$31,$A16+1)*Settings!$B$24*SUMPRODUCT(Sheep!$F$5:$F$23/INDEX('Rebirth Odds'!$C$9:$AB$27,0,$A16+1))/MAX(SUMPRODUCT(D$35:D$53/INDEX('Rebirth Odds'!$C$9:$AB$27,0,$A16+1)),Settings!$B$23) -> 73196.362 | E16: =60*INDEX(Rebirths!$C$6:$C$31,$A16+1)*Settings!$B$24*SUMPRODUCT(Sheep!$F$5:$F$23/INDEX('Rebirth Odds'!$C$9:$AB$27,0,$A16+1))/MAX(SUMPRODUCT(E$35:E$53/INDEX('Rebirth Odds'!$C$9:$AB$27,0,$A16+1)),Settings!$B$23) -> 79384.322 | F16: =60*INDEX(Rebirths!$C$6:$C$31,$A16+1)*Settings!$B$24*SUMPRODUCT(Sheep!$F$5:$F$23/INDEX('Rebirth Odds'!$C$9:$AB$27,0,$A16+1))/MAX(SUMPRODUCT(F$35:F$53/INDEX('Rebirth Odds'!$C$9:$AB$27,0,$A16+1)),Settings!$B$23) -> 79384.322
A17: 11 | B17: =60*INDEX(Rebirths!$C$6:$C$31,$A17+1)*Settings!$B$24*SUMPRODUCT(Sheep!$F$5:$F$23/INDEX('Rebirth Odds'!$C$9:$AB$27,0,$A17+1))/MAX(SUMPRODUCT(B$35:B$53/INDEX('Rebirth Odds'!$C$9:$AB$27,0,$A17+1)),Settings!$B$23) -> 69073.288 | C17: =60*INDEX(Rebirths!$C$6:$C$31,$A17+1)*Settings!$B$24*SUMPRODUCT(Sheep!$F$5:$F$23/INDEX('Rebirth Odds'!$C$9:$AB$27,0,$A17+1))/MAX(SUMPRODUCT(C$35:C$53/INDEX('Rebirth Odds'!$C$9:$AB$27,0,$A17+1)),Settings!$B$23) -> 87397.77 | D17: =60*INDEX(Rebirths!$C$6:$C$31,$A17+1)*Settings!$B$24*SUMPRODUCT(Sheep!$F$5:$F$23/INDEX('Rebirth Odds'!$C$9:$AB$27,0,$A17+1))/MAX(SUMPRODUCT(D$35:D$53/INDEX('Rebirth Odds'!$C$9:$AB$27,0,$A17+1)),Settings!$B$23) -> 110709.92 | E17: =60*INDEX(Rebirths!$C$6:$C$31,$A17+1)*Settings!$B$24*SUMPRODUCT(Sheep!$F$5:$F$23/INDEX('Rebirth Odds'!$C$9:$AB$27,0,$A17+1))/MAX(SUMPRODUCT(E$35:E$53/INDEX('Rebirth Odds'!$C$9:$AB$27,0,$A17+1)),Settings!$B$23) -> 120930.07 | F17: =60*INDEX(Rebirths!$C$6:$C$31,$A17+1)*Settings!$B$24*SUMPRODUCT(Sheep!$F$5:$F$23/INDEX('Rebirth Odds'!$C$9:$AB$27,0,$A17+1))/MAX(SUMPRODUCT(F$35:F$53/INDEX('Rebirth Odds'!$C$9:$AB$27,0,$A17+1)),Settings!$B$23) -> 120930.07
... A31: 25 | B31: =60*INDEX(Rebirths!$C$6:$C$31,$A31+1)*Settings!$B$24*SUMPRODUCT(Sheep!$F$5:$F$23/INDEX('Rebirth Odds'!$C$9:$AB$27,0,$A31+1))/MAX(SUMPRODUCT(B$35:B$53/INDEX('Rebirth Odds'!$C$9:$AB$27,0,$A31+1)),Settings!$B$23) -> 22751007 | C31: =60*INDEX(Rebirths!$C$6:$C$31,$A31+1)*Settings!$B$24*SUMPRODUCT(Sheep!$F$5:$F$23/INDEX('Rebirth Odds'!$C$9:$AB$27,0,$A31+1))/MAX(SUMPRODUCT(C$35:C$53/INDEX('Rebirth Odds'!$C$9:$AB$27,0,$A31+1)),Settings!$B$23) -> 28952267 | D31: =60*INDEX(Rebirths!$C$6:$C$31,$A31+1)*Settings!$B$24*SUMPRODUCT(Sheep!$F$5:$F$23/INDEX('Rebirth Odds'!$C$9:$AB$27,0,$A31+1))/MAX(SUMPRODUCT(D$35:D$53/INDEX('Rebirth Odds'!$C$9:$AB$27,0,$A31+1)),Settings!$B$23) -> 36617220 | E31: =60*INDEX(Rebirths!$C$6:$C$31,$A31+1)*Settings!$B$24*SUMPRODUCT(Sheep!$F$5:$F$23/INDEX('Rebirth Odds'!$C$9:$AB$27,0,$A31+1))/MAX(SUMPRODUCT(E$35:E$53/INDEX('Rebirth Odds'!$C$9:$AB$27,0,$A31+1)),Settings!$B$23) -> 44682238 | F31: =60*INDEX(Rebirths!$C$6:$C$31,$A31+1)*Settings!$B$24*SUMPRODUCT(Sheep!$F$5:$F$23/INDEX('Rebirth Odds'!$C$9:$AB$27,0,$A31+1))/MAX(SUMPRODUCT(F$35:F$53/INDEX('Rebirth Odds'!$C$9:$AB$27,0,$A31+1)),Settings!$B$23) -> 44682238
A33: Seconds of swinging to shear each sheep bare (before the spawn-interval cap)
A34: Sheep | B34: DefaultShear | C34: SteelShears | D34: LargeShears | E34: ElectricShears | F34: MasterShears
A35: =Sheep!A5 -> Basic Sheep | B35: =CEILING(Sheep!$E5/Shears!$F$5,1)*Settings!$B$5/Settings!$B$13 -> 1.75 | C35: =CEILING(Sheep!$E5/Shears!$F$6,1)*Settings!$B$5/Settings!$B$13 -> 1.4 | D35: =CEILING(Sheep!$E5/Shears!$F$7,1)*Settings!$B$5/Settings!$B$13 -> 1.05 | E35: =CEILING(Sheep!$E5/Shears!$F$8,1)*Settings!$B$5/Settings!$B$13 -> 1.05 | F35: =CEILING(Sheep!$E5/Shears!$F$9,1)*Settings!$B$5/Settings!$B$13 -> 0.7
A36: =Sheep!A6 -> Grey Sheep | B36: =CEILING(Sheep!$E6/Shears!$F$5,1)*Settings!$B$5/Settings!$B$13 -> 2.1 | C36: =CEILING(Sheep!$E6/Shears!$F$6,1)*Settings!$B$5/Settings!$B$13 -> 1.75 | D36: =CEILING(Sheep!$E6/Shears!$F$7,1)*Settings!$B$5/Settings!$B$13 -> 1.4 | E36: =CEILING(Sheep!$E6/Shears!$F$8,1)*Settings!$B$5/Settings!$B$13 -> 1.05 | F36: =CEILING(Sheep!$E6/Shears!$F$9,1)*Settings!$B$5/Settings!$B$13 -> 0.7
A37: =Sheep!A7 -> Brown Sheep | B37: =CEILING(Sheep!$E7/Shears!$F$5,1)*Settings!$B$5/Settings!$B$13 -> 2.1 | C37: =CEILING(Sheep!$E7/Shears!$F$6,1)*Settings!$B$5/Settings!$B$13 -> 1.75 | D37: =CEILING(Sheep!$E7/Shears!$F$7,1)*Settings!$B$5/Settings!$B$13 -> 1.4 | E37: =CEILING(Sheep!$E7/Shears!$F$8,1)*Settings!$B$5/Settings!$B$13 -> 1.05 | F37: =CEILING(Sheep!$E7/Shears!$F$9,1)*Settings!$B$5/Settings!$B$13 -> 0.7
A38: =Sheep!A8 -> Black Sheep | B38: =CEILING(Sheep!$E8/Shears!$F$5,1)*Settings!$B$5/Settings!$B$13 -> 2.45 | C38: =CEILING(Sheep!$E8/Shears!$F$6,1)*Settings!$B$5/Settings!$B$13 -> 1.75 | D38: =CEILING(Sheep!$E8/Shears!$F$7,1)*Settings!$B$5/Settings!$B$13 -> 1.4 | E38: =CEILING(Sheep!$E8/Shears!$F$8,1)*Settings!$B$5/Settings!$B$13 -> 1.05 | F38: =CEILING(Sheep!$E8/Shears!$F$9,1)*Settings!$B$5/Settings!$B$13 -> 1.05
A39: =Sheep!A9 -> Fluffy Sheep | B39: =CEILING(Sheep!$E9/Shears!$F$5,1)*Settings!$B$5/Settings!$B$13 -> 2.8 | C39: =CEILING(Sheep!$E9/Shears!$F$6,1)*Settings!$B$5/Settings!$B$13 -> 2.1 | D39: =CEILING(Sheep!$E9/Shears!$F$7,1)*Settings!$B$5/Settings!$B$13 -> 1.75 | E39: =CEILING(Sheep!$E9/Shears!$F$8,1)*Settings!$B$5/Settings!$B$13 -> 1.4 | F39: =CEILING(Sheep!$E9/Shears!$F$9,1)*Settings!$B$5/Settings!$B$13 -> 1.05
A40: =Sheep!A10 -> Cotton Candy Sheep | B40: =CEILING(Sheep!$E10/Shears!$F$5,1)*Settings!$B$5/Settings!$B$13 -> 2.8 | C40: =CEILING(Sheep!$E10/Shears!$F$6,1)*Settings!$B$5/Settings!$B$13 -> 2.1 | D40: =CEILING(Sheep!$E10/Shears!$F$7,1)*Settings!$B$5/Settings!$B$13 -> 1.75 | E40: =CEILING(Sheep!$E10/Shears!$F$8,1)*Settings!$B$5/Settings!$B$13 -> 1.4 | F40: =CEILING(Sheep!$E10/Shears!$F$9,1)*Settings!$B$5/Settings!$B$13 -> 1.05
A41: =Sheep!A11 -> Ice Sheep | B41: =CEILING(Sheep!$E11/Shears!$F$5,1)*Settings!$B$5/Settings!$B$13 -> 2.8 | C41: =CEILING(Sheep!$E11/Shears!$F$6,1)*Settings!$B$5/Settings!$B$13 -> 2.45 | D41: =CEILING(Sheep!$E11/Shears!$F$7,1)*Settings!$B$5/Settings!$B$13 -> 1.75 | E41: =CEILING(Sheep!$E11/Shears!$F$8,1)*Settings!$B$5/Settings!$B$13 -> 1.4 | F41: =CEILING(Sheep!$E11/Shears!$F$9,1)*Settings!$B$5/Settings!$B$13 -> 1.05
A42: =Sheep!A12 -> Golden Sheep | B42: =CEILING(Sheep!$E12/Shears!$F$5,1)*Settings!$B$5/Settings!$B$13 -> 3.15 | C42: =CEILING(Sheep!$E12/Shears!$F$6,1)*Settings!$B$5/Settings!$B$13 -> 2.45 | D42: =CEILING(Sheep!$E12/Shears!$F$7,1)*Settings!$B$5/Settings!$B$13 -> 2.1 | E42: =CEILING(Sheep!$E12/Shears!$F$8,1)*Settings!$B$5/Settings!$B$13 -> 1.4 | F42: =CEILING(Sheep!$E12/Shears!$F$9,1)*Settings!$B$5/Settings!$B$13 -> 1.05
A43: =Sheep!A13 -> Stone Sheep | B43: =CEILING(Sheep!$E13/Shears!$F$5,1)*Settings!$B$5/Settings!$B$13 -> 4.2 | C43: =CEILING(Sheep!$E13/Shears!$F$6,1)*Settings!$B$5/Settings!$B$13 -> 3.15 | D43: =CEILING(Sheep!$E13/Shears!$F$7,1)*Settings!$B$5/Settings!$B$13 -> 2.45 | E43: =CEILING(Sheep!$E13/Shears!$F$8,1)*Settings!$B$5/Settings!$B$13 -> 1.75 | F43: =CEILING(Sheep!$E13/Shears!$F$9,1)*Settings!$B$5/Settings!$B$13 -> 1.4
A44: =Sheep!A14 -> Mummy Sheep | B44: =CEILING(Sheep!$E14/Shears!$F$5,1)*Settings!$B$5/Settings!$B$13 -> 3.5 | C44: =CEILING(Sheep!$E14/Shears!$F$6,1)*Settings!$B$5/Settings!$B$13 -> 2.8 | D44: =CEILING(Sheep!$E14/Shears!$F$7,1)*Settings!$B$5/Settings!$B$13 -> 2.1 | E44: =CEILING(Sheep!$E14/Shears!$F$8,1)*Settings!$B$5/Settings!$B$13 -> 1.75 | F44: =CEILING(Sheep!$E14/Shears!$F$9,1)*Settings!$B$5/Settings!$B$13 -> 1.4
A45: =Sheep!A15 -> Luck Sheep | B45: =CEILING(Sheep!$E15/Shears!$F$5,1)*Settings!$B$5/Settings!$B$13 -> 3.5 | C45: =CEILING(Sheep!$E15/Shears!$F$6,1)*Settings!$B$5/Settings!$B$13 -> 2.8 | D45: =CEILING(Sheep!$E15/Shears!$F$7,1)*Settings!$B$5/Settings!$B$13 -> 2.1 | E45: =CEILING(Sheep!$E15/Shears!$F$8,1)*Settings!$B$5/Settings!$B$13 -> 1.75 | F45: =CEILING(Sheep!$E15/Shears!$F$9,1)*Settings!$B$5/Settings!$B$13 -> 1.4
A46: =Sheep!A16 -> Emerald Sheep | B46: =CEILING(Sheep!$E16/Shears!$F$5,1)*Settings!$B$5/Settings!$B$13 -> 3.5 | C46: =CEILING(Sheep!$E16/Shears!$F$6,1)*Settings!$B$5/Settings!$B$13 -> 2.8 | D46: =CEILING(Sheep!$E16/Shears!$F$7,1)*Settings!$B$5/Settings!$B$13 -> 2.1 | E46: =CEILING(Sheep!$E16/Shears!$F$8,1)*Settings!$B$5/Settings!$B$13 -> 1.75 | F46: =CEILING(Sheep!$E16/Shears!$F$9,1)*Settings!$B$5/Settings!$B$13 -> 1.4
... A53: =Sheep!A23 -> Obsidian Sheep | B53: =CEILING(Sheep!$E23/Shears!$F$5,1)*Settings!$B$5/Settings!$B$13 -> 4.9 | C53: =CEILING(Sheep!$E23/Shears!$F$6,1)*Settings!$B$5/Settings!$B$13 -> 3.85 | D53: =CEILING(Sheep!$E23/Shears!$F$7,1)*Settings!$B$5/Settings!$B$13 -> 2.8 | E53: =CEILING(Sheep!$E23/Shears!$F$8,1)*Settings!$B$5/Settings!$B$13 -> 2.1 | F53: =CEILING(Sheep!$E23/Shears!$F$9,1)*Settings!$B$5/Settings!$B$13 -> 1.75

Sheet Rebirths
A1: Rebirths
A2: Luck each rebirth grants, the Luck a farm starts with, and what a run at that rebirth is expected to turn up.
A5: Rebirths done | B5: Wool to rebirth again | C5: Wool multiplier | D5: Luck from this rebirth | E5: Starting Luck | F5: Luck factor | G5: Common odds | H5: Uncommon odds | I5: Rare odds | J5: Epic odds | K5: Legendary odds | L5: Mythic odds | M5: Avg wool per sheep | N5: Sheep to shear for next rebirth | O5: Rarest sheep expected this run | P5: Its odds
A6: 0 | B6: =IF(A6>=Settings!$B$15,"max",FLOOR(Settings!$B$16*Settings!$B$17^A6,1)) -> 1500 | C6: =Settings!$B$18^A6 -> 1 | D6: =IF(A6=0,0,FLOOR(Settings!$B$19*Settings!$B$20^(A6-1)*IF(MOD(A6,Settings!$B$21)=0,Settings!$B$22,1),1)) -> 0 | E6: =SUM($D$6:D6) -> 0 | F6: =1+Settings!$B$14*LOG10(1+E6) -> 1 | G6: =IFERROR(1/SUMPRODUCT((Sheep!$C$5:$C$23="Common")/INDEX('Rebirth Odds'!$C$9:$AB$27,0,$A6+1)),"-") -> 1.4070533 | H6: =IFERROR(1/SUMPRODUCT((Sheep!$C$5:$C$23="Uncommon")/INDEX('Rebirth Odds'!$C$9:$AB$27,0,$A6+1)),"-") -> 5.0251905 | I6: =IFERROR(1/SUMPRODUCT((Sheep!$C$5:$C$23="Rare")/INDEX('Rebirth Odds'!$C$9:$AB$27,0,$A6+1)),"-") -> 14.656806 | J6: =IFERROR(1/SUMPRODUCT((Sheep!$C$5:$C$23="Epic")/INDEX('Rebirth Odds'!$C$9:$AB$27,0,$A6+1)),"-") -> 48.743187 | K6: =IFERROR(1/SUMPRODUCT((Sheep!$C$5:$C$23="Legendary")/INDEX('Rebirth Odds'!$C$9:$AB$27,0,$A6+1)),"-") -> 753.77857 | L6: =IFERROR(1/SUMPRODUCT((Sheep!$C$5:$C$23="Mythic")/INDEX('Rebirth Odds'!$C$9:$AB$27,0,$A6+1)),"-") -> 4397.0417 | M6: =C6*Settings!$B$24*SUMPRODUCT(Sheep!$F$5:$F$23/INDEX('Rebirth Odds'!$C$9:$AB$27,0,$A6+1)) -> 19.686626 | N6: =IF(ISNUMBER(B6),B6/M6,"-") -> 76.193857 | O6: =IF(ISNUMBER(N6),INDEX(Sheep!$A$5:$A$23,MATCH(P6,INDEX('Rebirth Odds'!$C$9:$AB$27,0,$A6+1),0)),"-") -> Ice Sheep | P6: =IF(ISNUMBER(N6),_xlfn.MAXIFS(INDEX('Rebirth Odds'!$C$9:$AB$27,0,$A6+1),INDEX('Rebirth Odds'!$C$9:$AB$27,0,$A6+1),"<="&N6),"-") -> 52.7645
A7: 1 | B7: =IF(A7>=Settings!$B$15,"max",FLOOR(Settings!$B$16*Settings!$B$17^A7,1)) -> 4500 | C7: =Settings!$B$18^A7 -> 1.5 | D7: =IF(A7=0,0,FLOOR(Settings!$B$19*Settings!$B$20^(A7-1)*IF(MOD(A7,Settings!$B$21)=0,Settings!$B$22,1),1)) -> 50 | E7: =SUM($D$6:D7) -> 50 | F7: =1+Settings!$B$14*LOG10(1+E7) -> 1.8537851 | G7: =IFERROR(1/SUMPRODUCT((Sheep!$C$5:$C$23="Common")/INDEX('Rebirth Odds'!$C$9:$AB$27,0,$A7+1)),"-") -> 2.0619131 | H7: =IFERROR(1/SUMPRODUCT((Sheep!$C$5:$C$23="Uncommon")/INDEX('Rebirth Odds'!$C$9:$AB$27,0,$A7+1)),"-") -> 3.9723996 | I7: =IFERROR(1/SUMPRODUCT((Sheep!$C$5:$C$23="Rare")/INDEX('Rebirth Odds'!$C$9:$AB$27,0,$A7+1)),"-") -> 6.2500047 | J7: =IFERROR(1/SUMPRODUCT((Sheep!$C$5:$C$23="Epic")/INDEX('Rebirth Odds'!$C$9:$AB$27,0,$A7+1)),"-") -> 11.212322 | K7: =IFERROR(1/SUMPRODUCT((Sheep!$C$5:$C$23="Legendary")/INDEX('Rebirth Odds'!$C$9:$AB$27,0,$A7+1)),"-") -> 93.533253 | L7: =IFERROR(1/SUMPRODUCT((Sheep!$C$5:$C$23="Mythic")/INDEX('Rebirth Odds'!$C$9:$AB$27,0,$A7+1)),"-") -> 294.32249 | M7: =C7*Settings!$B$24*SUMPRODUCT(Sheep!$F$5:$F$23/INDEX('Rebirth Odds'!$C$9:$AB$27,0,$A7+1)) -> 38.502162 | N7: =IF(ISNUMBER(B7),B7/M7,"-") -> 116.87655 | O7: =IF(ISNUMBER(N7),INDEX(Sheep!$A$5:$A$23,MATCH(P7,INDEX('Rebirth Odds'!$C$9:$AB$27,0,$A7+1),0)),"-") -> Luck Sheep | P7: =IF(ISNUMBER(N7),_xlfn.MAXIFS(INDEX('Rebirth Odds'!$C$9:$AB$27,0,$A7+1),INDEX('Rebirth Odds'!$C$9:$AB$27,0,$A7+1),"<="&N7),"-") -> 115.5937
A8: 2 | B8: =IF(A8>=Settings!$B$15,"max",FLOOR(Settings!$B$16*Settings!$B$17^A8,1)) -> 13500 | C8: =Settings!$B$18^A8 -> 2.25 | D8: =IF(A8=0,0,FLOOR(Settings!$B$19*Settings!$B$20^(A8-1)*IF(MOD(A8,Settings!$B$21)=0,Settings!$B$22,1),1)) -> 72 | E8: =SUM($D$6:D8) -> 122 | F8: =1+Settings!$B$14*LOG10(1+E8) -> 2.0449526 | G8: =IFERROR(1/SUMPRODUCT((Sheep!$C$5:$C$23="Common")/INDEX('Rebirth Odds'!$C$9:$AB$27,0,$A8+1)),"-") -> 2.2649874 | H8: =IFERROR(1/SUMPRODUCT((Sheep!$C$5:$C$23="Uncommon")/INDEX('Rebirth Odds'!$C$9:$AB$27,0,$A8+1)),"-") -> 3.9557107 | I8: =IFERROR(1/SUMPRODUCT((Sheep!$C$5:$C$23="Rare")/INDEX('Rebirth Odds'!$C$9:$AB$27,0,$A8+1)),"-") -> 5.6419351 | J8: =IFERROR(1/SUMPRODUCT((Sheep!$C$5:$C$23="Epic")/INDEX('Rebirth Odds'!$C$9:$AB$27,0,$A8+1)),"-") -> 9.1752825 | K8: =IFERROR(1/SUMPRODUCT((Sheep!$C$5:$C$23="Legendary")/INDEX('Rebirth Odds'!$C$9:$AB$27,0,$A8+1)),"-") -> 69.385077 | L8: =IFERROR(1/SUMPRODUCT((Sheep!$C$5:$C$23="Mythic")/INDEX('Rebirth Odds'!$C$9:$AB$27,0,$A8+1)),"-") -> 197.92453 | M8: =C8*Settings!$B$24*SUMPRODUCT(Sheep!$F$5:$F$23/INDEX('Rebirth Odds'!$C$9:$AB$27,0,$A8+1)) -> 61.25583 | N8: =IF(ISNUMBER(B8),B8/M8,"-") -> 220.38718 | O8: =IF(ISNUMBER(N8),INDEX(Sheep!$A$5:$A$23,MATCH(P8,INDEX('Rebirth Odds'!$C$9:$AB$27,0,$A8+1),0)),"-") -> Pumpkin Sheep | P8: =IF(ISNUMBER(N8),_xlfn.MAXIFS(INDEX('Rebirth Odds'!$C$9:$AB$27,0,$A8+1),INDEX('Rebirth Odds'!$C$9:$AB$27,0,$A8+1),"<="&N8),"-") -> 194.27822
A9: 3 | B9: =IF(A9>=Settings!$B$15,"max",FLOOR(Settings!$B$16*Settings!$B$17^A9,1)) -> 40500 | C9: =Settings!$B$18^A9 -> 3.375 | D9: =IF(A9=0,0,FLOOR(Settings!$B$19*Settings!$B$20^(A9-1)*IF(MOD(A9,Settings!$B$21)=0,Settings!$B$22,1),1)) -> 105 | E9: =SUM($D$6:D9) -> 227 | F9: =1+Settings!$B$14*LOG10(1+E9) -> 2.1789674 | G9: =IFERROR(1/SUMPRODUCT((Sheep!$C$5:$C$23="Common")/INDEX('Rebirth Odds'!$C$9:$AB$27,0,$A9+1)),"-") -> 2.4223474 | H9: =IFERROR(1/SUMPRODUCT((Sheep!$C$5:$C$23="Uncommon")/INDEX('Rebirth Odds'!$C$9:$AB$27,0,$A9+1)),"-") -> 3.9703397 | I9: =IFERROR(1/SUMPRODUCT((Sheep!$C$5:$C$23="Rare")/INDEX('Rebirth Odds'!$C$9:$AB$27,0,$A9+1)),"-") -> 5.3145161 | J9: =IFERROR(1/SUMPRODUCT((Sheep!$C$5:$C$23="Epic")/INDEX('Rebirth Odds'!$C$9:$AB$27,0,$A9+1)),"-") -> 8.1112462 | K9: =IFERROR(1/SUMPRODUCT((Sheep!$C$5:$C$23="Legendary")/INDEX('Rebirth Odds'!$C$9:$AB$27,0,$A9+1)),"-") -> 57.566087 | L9: =IFERROR(1/SUMPRODUCT((Sheep!$C$5:$C$23="Mythic")/INDEX('Rebirth Odds'!$C$9:$AB$27,0,$A9+1)),"-") -> 154.11069 | M9: =C9*Settings!$B$24*SUMPRODUCT(Sheep!$F$5:$F$23/INDEX('Rebirth Odds'!$C$9:$AB$27,0,$A9+1)) -> 95.652199 | N9: =IF(ISNUMBER(B9),B9/M9,"-") -> 423.40898 | O9: =IF(ISNUMBER(N9),INDEX(Sheep!$A$5:$A$23,MATCH(P9,INDEX('Rebirth Odds'!$C$9:$AB$27,0,$A9+1),0)),"-") -> Vampire Sheep | P9: =IF(ISNUMBER(N9),_xlfn.MAXIFS(INDEX('Rebirth Odds'!$C$9:$AB$27,0,$A9+1),INDEX('Rebirth Odds'!$C$9:$AB$27,0,$A9+1),"<="&N9),"-") -> 402.96261
A10: 4 | B10: =IF(A10>=Settings!$B$15,"max",FLOOR(Settings!$B$16*Settings!$B$17^A10,1)) -> 121500 | C10: =Settings!$B$18^A10 -> 5.0625 | D10: =IF(A10=0,0,FLOOR(Settings!$B$19*Settings!$B$20^(A10-1)*IF(MOD(A10,Settings!$B$21)=0,Settings!$B$22,1),1)) -> 152 | E10: =SUM($D$6:D10) -> 379 | F10: =1+Settings!$B$14*LOG10(1+E10) -> 2.2898918 | G10: =IFERROR(1/SUMPRODUCT((Sheep!$C$5:$C$23="Common")/INDEX('Rebirth Odds'!$C$9:$AB$27,0,$A10+1)),"-") -> 2.5626385 | H10: =IFERROR(1/SUMPRODUCT((Sheep!$C$5:$C$23="Uncommon")/INDEX('Rebirth Odds'!$C$9:$AB$27,0,$A10+1)),"-") -> 3.9968178 | I10: =IFERROR(1/SUMPRODUCT((Sheep!$C$5:$C$23="Rare")/INDEX('Rebirth Odds'!$C$9:$AB$27,0,$A10+1)),"-") -> 5.0908018 | J10: =IFERROR(1/SUMPRODUCT((Sheep!$C$5:$C$23="Epic")/INDEX('Rebirth Odds'!$C$9:$AB$27,0,$A10+1)),"-") -> 7.3934275 | K10: =IFERROR(1/SUMPRODUCT((Sheep!$C$5:$C$23="Legendary")/INDEX('Rebirth Odds'!$C$9:$AB$27,0,$A10+1)),"-") -> 49.929903 | L10: =IFERROR(1/SUMPRODUCT((Sheep!$C$5:$C$23="Mythic")/INDEX('Rebirth Odds'!$C$9:$AB$27,0,$A10+1)),"-") -> 127.19281 | M10: =C10*Settings!$B$24*SUMPRODUCT(Sheep!$F$5:$F$23/INDEX('Rebirth Odds'!$C$9:$AB$27,0,$A10+1)) -> 148.21368 | N10: =IF(ISNUMBER(B10),B10/M10,"-") -> 819.76237 | O10: =IF(ISNUMBER(N10),INDEX(Sheep!$A$5:$A$23,MATCH(P10,INDEX('Rebirth Odds'!$C$9:$AB$27,0,$A10+1),0)),"-") -> Obsidian Sheep | P10: =IF(ISNUMBER(N10),_xlfn.MAXIFS(INDEX('Rebirth Odds'!$C$9:$AB$27,0,$A10+1),INDEX('Rebirth Odds'!$C$9:$AB$27,0,$A10+1),"<="&N10),"-") -> 508.77123
A11: 5 | B11: =IF(A11>=Settings!$B$15,"max",FLOOR(Settings!$B$16*Settings!$B$17^A11,1)) -> 364500 | C11: =Settings!$B$18^A11 -> 7.59375 | D11: =IF(A11=0,0,FLOOR(Settings!$B$19*Settings!$B$20^(A11-1)*IF(MOD(A11,Settings!$B$21)=0,Settings!$B$22,1),1)) -> 442 | E11: =SUM($D$6:D11) -> 821 | F11: =1+Settings!$B$14*LOG10(1+E11) -> 2.4574359 | G11: =IFERROR(1/SUMPRODUCT((Sheep!$C$5:$C$23="Common")/INDEX('Rebirth Odds'!$C$9:$AB$27,0,$A11+1)),"-") -> 2.7929741 | H11: =IFERROR(1/SUMPRODUCT((Sheep!$C$5:$C$23="Uncommon")/INDEX('Rebirth Odds'!$C$9:$AB$27,0,$A11+1)),"-") -> 4.0590713 | I11: =IFERROR(1/SUMPRODUCT((Sheep!$C$5:$C$23="Rare")/INDEX('Rebirth Odds'!$C$9:$AB$27,0,$A11+1)),"-") -> 4.817606 | J11: =IFERROR(1/SUMPRODUCT((Sheep!$C$5:$C$23="Epic")/INDEX('Rebirth Odds'!$C$9:$AB$27,0,$A11+1)),"-") -> 6.5196409 | K11: =IFERROR(1/SUMPRODUCT((Sheep!$C$5:$C$23="Legendary")/INDEX('Rebirth Odds'!$C$9:$AB$27,0,$A11+1)),"-") -> 41.027149 | L11: =IFERROR(1/SUMPRODUCT((Sheep!$C$5:$C$23="Mythic")/INDEX('Rebirth Odds'!$C$9:$AB$27,0,$A11+1)),"-") -> 97.388109 | M11: =C11*Settings!$B$24*SUMPRODUCT(Sheep!$F$5:$F$23/INDEX('Rebirth Odds'!$C$9:$AB$27,0,$A11+1)) -> 233.14407 | N11: =IF(ISNUMBER(B11),B11/M11,"-") -> 1563.411 | O11: =IF(ISNUMBER(N11),INDEX(Sheep!$A$5:$A$23,MATCH(P11,INDEX('Rebirth Odds'!$C$9:$AB$27,0,$A11+1),0)),"-") -> Obsidian Sheep | P11: =IF(ISNUMBER(N11),_xlfn.MAXIFS(INDEX('Rebirth Odds'!$C$9:$AB$27,0,$A11+1),INDEX('Rebirth Odds'!$C$9:$AB$27,0,$A11+1),"<="&N11),"-") -> 389.55244
A12: 6 | B12: =IF(A12>=Settings!$B$15,"max",FLOOR(Settings!$B$16*Settings!$B$17^A12,1)) -> 1093500 | C12: =Settings!$B$18^A12 -> 11.390625 | D12: =IF(A12=0,0,FLOOR(Settings!$B$19*Settings!$B$20^(A12-1)*IF(MOD(A12,Settings!$B$21)=0,Settings!$B$22,1),1)) -> 320 | E12: =SUM($D$6:D12) -> 1141 | F12: =1+Settings!$B$14*LOG10(1+E12) -> 2.5288331 | G12: =IFERROR(1/SUMPRODUCT((Sheep!$C$5:$C$23="Common")/INDEX('Rebirth Odds'!$C$9:$AB$27,0,$A12+1)),"-") -> 2.8982544 | H12: =IFERROR(1/SUMPRODUCT((Sheep!$C$5:$C$23="Uncommon")/INDEX('Rebirth Odds'!$C$9:$AB$27,0,$A12+1)),"-") -> 4.0931562 | I12: =IFERROR(1/SUMPRODUCT((Sheep!$C$5:$C$23="Rare")/INDEX('Rebirth Odds'!$C$9:$AB$27,0,$A12+1)),"-") -> 4.7209017 | J12: =IFERROR(1/SUMPRODUCT((Sheep!$C$5:$C$23="Epic")/INDEX('Rebirth Odds'!$C$9:$AB$27,0,$A12+1)),"-") -> 6.2083958 | K12: =IFERROR(1/SUMPRODUCT((Sheep!$C$5:$C$23="Legendary")/INDEX('Rebirth Odds'!$C$9:$AB$27,0,$A12+1)),"-") -> 37.965498 | L12: =IFERROR(1/SUMPRODUCT((Sheep!$C$5:$C$23="Mythic")/INDEX('Rebirth Odds'!$C$9:$AB$27,0,$A12+1)),"-") -> 87.576127 | M12: =C12*Settings!$B$24*SUMPRODUCT(Sheep!$F$5:$F$23/INDEX('Rebirth Odds'!$C$9:$AB$27,0,$A12+1)) -> 356.6649 | N12: =IF(ISNUMBER(B12),B12/M12,"-") -> 3065.903 | O12: =IF(ISNUMBER(N12),INDEX(Sheep!$A$5:$A$23,MATCH(P12,INDEX('Rebirth Odds'!$C$9:$AB$27,0,$A12+1),0)),"-") -> Obsidian Sheep | P12: =IF(ISNUMBER(N12),_xlfn.MAXIFS(INDEX('Rebirth Odds'!$C$9:$AB$27,0,$A12+1),INDEX('Rebirth Odds'!$C$9:$AB$27,0,$A12+1),"<="&N12),"-") -> 350.30451
A13: 7 | B13: =IF(A13>=Settings!$B$15,"max",FLOOR(Settings!$B$16*Settings!$B$17^A13,1)) -> 3280500 | C13: =Settings!$B$18^A13 -> 17.085938 | D13: =IF(A13=0,0,FLOOR(Settings!$B$19*Settings!$B$20^(A13-1)*IF(MOD(A13,Settings!$B$21)=0,Settings!$B$22,1),1)) -> 464 | E13: =SUM($D$6:D13) -> 1605 | F13: =1+Settings!$B$14*LOG10(1+E13) -> 2.6028728 | G13: =IFERROR(1/SUMPRODUCT((Sheep!$C$5:$C$23="Common")/INDEX('Rebirth Odds'!$C$9:$AB$27,0,$A13+1)),"-") -> 3.0121541 | H13: =IFERROR(1/SUMPRODUCT((Sheep!$C$5:$C$23="Uncommon")/INDEX('Rebirth Odds'!$C$9:$AB$27,0,$A13+1)),"-") -> 4.1330078 | I13: =IFERROR(1/SUMPRODUCT((Sheep!$C$5:$C$23="Rare")/INDEX('Rebirth Odds'!$C$9:$AB$27,0,$A13+1)),"-") -> 4.6312698 | J13: =IFERROR(1/SUMPRODUCT((Sheep!$C$5:$C$23="Epic")/INDEX('Rebirth Odds'!$C$9:$AB$27,0,$A13+1)),"-") -> 5.9172748 | K13: =IFERROR(1/SUMPRODUCT((Sheep!$C$5:$C$23="Legendary")/INDEX('Rebirth Odds'!$C$9:$AB$27,0,$A13+1)),"-") -> 35.155936 | L13: =IFERROR(1/SUMPRODUCT((Sheep!$C$5:$C$23="Mythic")/INDEX('Rebirth Odds'!$C$9:$AB$27,0,$A13+1)),"-") -> 78.788442 | M13: =C13*Settings!$B$24*SUMPRODUCT(Sheep!$F$5:$F$23/INDEX('Rebirth Odds'!$C$9:$AB$27,0,$A13+1)) -> 545.81823 | N13: =IF(ISNUMBER(B13),B13/M13,"-") -> 6010.2427 | O13: =IF(ISNUMBER(N13),INDEX(Sheep!$A$5:$A$23,MATCH(P13,INDEX('Rebirth Odds'!$C$9:$AB$27,0,$A13+1),0)),"-") -> Obsidian Sheep | P13: =IF(ISNUMBER(N13),_xlfn.MAXIFS(INDEX('Rebirth Odds'!$C$9:$AB$27,0,$A13+1),INDEX('Rebirth Odds'!$C$9:$AB$27,0,$A13+1),"<="&N13),"-") -> 315.15377
A14: 8 | B14: =IF(A14>=Settings!$B$15,"max",FLOOR(Settings!$B$16*Settings!$B$17^A14,1)) -> 9841500 | C14: =Settings!$B$18^A14 -> 25.628906 | D14: =IF(A14=0,0,FLOOR(Settings!$B$19*Settings!$B$20^(A14-1)*IF(MOD(A14,Settings!$B$21)=0,Settings!$B$22,1),1)) -> 673 | E14: =SUM($D$6:D14) -> 2278 | F14: =1+Settings!$B$14*LOG10(1+E14) -> 2.6788722 | G14: =IFERROR(1/SUMPRODUCT((Sheep!$C$5:$C$23="Common")/INDEX('Rebirth Odds'!$C$9:$AB$27,0,$A14+1)),"-") -> 3.1342442 | H14: =IFERROR(1/SUMPRODUCT((Sheep!$C$5:$C$23="Uncommon")/INDEX('Rebirth Odds'!$C$9:$AB$27,0,$A14+1)),"-") -> 4.1785231 | I14: =IFERROR(1/SUMPRODUCT((Sheep!$C$5:$C$23="Rare")/INDEX('Rebirth Odds'!$C$9:$AB$27,0,$A14+1)),"-") -> 4.5494366 | J14: =IFERROR(1/SUMPRODUCT((Sheep!$C$5:$C$23="Epic")/INDEX('Rebirth Odds'!$C$9:$AB$27,0,$A14+1)),"-") -> 5.6478119 | K14: =IFERROR(1/SUMPRODUCT((Sheep!$C$5:$C$23="Legendary")/INDEX('Rebirth Odds'!$C$9:$AB$27,0,$A14+1)),"-") -> 32.60304 | L14: =IFERROR(1/SUMPRODUCT((Sheep!$C$5:$C$23="Mythic")/INDEX('Rebirth Odds'!$C$9:$AB$27,0,$A14+1)),"-") -> 70.994205 | M14: =C14*Settings!$B$24*SUMPRODUCT(Sheep!$F$5:$F$23/INDEX('Rebirth Odds'!$C$9:$AB$27,0,$A14+1)) -> 835.38988 | N14: =IF(ISNUMBER(B14),B14/M14,"-") -> 11780.727 | O14: =IF(ISNUMBER(N14),INDEX(Sheep!$A$5:$A$23,MATCH(P14,INDEX('Rebirth Odds'!$C$9:$AB$27,0,$A14+1),0)),"-") -> Obsidian Sheep | P14: =IF(ISNUMBER(N14),_xlfn.MAXIFS(INDEX('Rebirth Odds'!$C$9:$AB$27,0,$A14+1),INDEX('Rebirth Odds'!$C$9:$AB$27,0,$A14+1),"<="&N14),"-") -> 283.97682
A15: 9 | B15: =IF(A15>=Settings!$B$15,"max",FLOOR(Settings!$B$16*Settings!$B$17^A15,1)) -> 29524500 | C15: =Settings!$B$18^A15 -> 38.443359 | D15: =IF(A15=0,0,FLOOR(Settings!$B$19*Settings!$B$20^(A15-1)*IF(MOD(A15,Settings!$B$21)=0,Settings!$B$22,1),1)) -> 977 | E15: =SUM($D$6:D15) -> 3255 | F15: =1+Settings!$B$14*LOG10(1+E15) -> 2.7563422 | G15: =IFERROR(1/SUMPRODUCT((Sheep!$C$5:$C$23="Common")/INDEX('Rebirth Odds'!$C$9:$AB$27,0,$A15+1)),"-") -> 3.264285 | H15: =IFERROR(1/SUMPRODUCT((Sheep!$C$5:$C$23="Uncommon")/INDEX('Rebirth Odds'!$C$9:$AB$27,0,$A15+1)),"-") -> 4.2295767 | I15: =IFERROR(1/SUMPRODUCT((Sheep!$C$5:$C$23="Rare")/INDEX('Rebirth Odds'!$C$9:$AB$27,0,$A15+1)),"-") -> 4.4755928 | J15: =IFERROR(1/SUMPRODUCT((Sheep!$C$5:$C$23="Epic")/INDEX('Rebirth Odds'!$C$9:$AB$27,0,$A15+1)),"-") -> 5.3999785 | K15: =IFERROR(1/SUMPRODUCT((Sheep!$C$5:$C$23="Legendary")/INDEX('Rebirth Odds'!$C$9:$AB$27,0,$A15+1)),"-") -> 30.296242 | L15: =IFERROR(1/SUMPRODUCT((Sheep!$C$5:$C$23="Mythic")/INDEX('Rebirth Odds'!$C$9:$AB$27,0,$A15+1)),"-") -> 64.116886 | M15: =C15*Settings!$B$24*SUMPRODUCT(Sheep!$F$5:$F$23/INDEX('Rebirth Odds'!$C$9:$AB$27,0,$A15+1)) -> 1278.539 | N15: =IF(ISNUMBER(B15),B15/M15,"-") -> 23092.373 | O15: =IF(ISNUMBER(N15),INDEX(Sheep!$A$5:$A$23,MATCH(P15,INDEX('Rebirth Odds'!$C$9:$AB$27,0,$A15+1),0)),"-") -> Obsidian Sheep | P15: =IF(ISNUMBER(N15),_xlfn.MAXIFS(INDEX('Rebirth Odds'!$C$9:$AB$27,0,$A15+1),INDEX('Rebirth Odds'!$C$9:$AB$27,0,$A15+1),"<="&N15),"-") -> 256.46754
A16: 10 | B16: =IF(A16>=Settings!$B$15,"max",FLOOR(Settings!$B$16*Settings!$B$17^A16,1)) -> 88573500 | C16: =Settings!$B$18^A16 -> 57.665039 | D16: =IF(A16=0,0,FLOOR(Settings!$B$19*Settings!$B$20^(A16-1)*IF(MOD(A16,Settings!$B$21)=0,Settings!$B$22,1),1)) -> 2833 | E16: =SUM($D$6:D16) -> 6088 | F16: =1+Settings!$B$14*LOG10(1+E16) -> 2.892273 | G16: =IFERROR(1/SUMPRODUCT((Sheep!$C$5:$C$23="Common")/INDEX('Rebirth Odds'!$C$9:$AB$27,0,$A16+1)),"-") -> 3.5067064 | H16: =IFERROR(1/SUMPRODUCT((Sheep!$C$5:$C$23="Uncommon")/INDEX('Rebirth Odds'!$C$9:$AB$27,0,$A16+1)),"-") -> 4.3301416 | I16: =IFERROR(1/SUMPRODUCT((Sheep!$C$5:$C$23="Rare")/INDEX('Rebirth Odds'!$C$9:$AB$27,0,$A16+1)),"-") -> 4.3666624 | J16: =IFERROR(1/SUMPRODUCT((Sheep!$C$5:$C$23="Epic")/INDEX('Rebirth Odds'!$C$9:$AB$27,0,$A16+1)),"-") -> 5.0209388 | K16: =IFERROR(1/SUMPRODUCT((Sheep!$C$5:$C$23="Legendary")/INDEX('Rebirth Odds'!$C$9:$AB$27,0,$A16+1)),"-") -> 26.845748 | L16: =IFERROR(1/SUMPRODUCT((Sheep!$C$5:$C$23="Mythic")/INDEX('Rebirth Odds'!$C$9:$AB$27,0,$A16+1)),"-") -> 54.144335 | M16: =C16*Settings!$B$24*SUMPRODUCT(Sheep!$F$5:$F$23/INDEX('Rebirth Odds'!$C$9:$AB$27,0,$A16+1)) -> 1984.6081 | N16: =IF(ISNUMBER(B16),B16/M16,"-") -> 44630.223 | O16: =IF(ISNUMBER(N16),INDEX(Sheep!$A$5:$A$23,MATCH(P16,INDEX('Rebirth Odds'!$C$9:$AB$27,0,$A16+1),0)),"-") -> Obsidian Sheep | P16: =IF(ISNUMBER(N16),_xlfn.MAXIFS(INDEX('Rebirth Odds'!$C$9:$AB$27,0,$A16+1),INDEX('Rebirth Odds'!$C$9:$AB$27,0,$A16+1),"<="&N16),"-") -> 216.57734
A17: 11 | B17: =IF(A17>=Settings!$B$15,"max",FLOOR(Settings!$B$16*Settings!$B$17^A17,1)) -> 265720500 | C17: =Settings!$B$18^A17 -> 86.497559 | D17: =IF(A17=0,0,FLOOR(Settings!$B$19*Settings!$B$20^(A17-1)*IF(MOD(A17,Settings!$B$21)=0,Settings!$B$22,1),1)) -> 2054 | E17: =SUM($D$6:D17) -> 8142 | F17: =1+Settings!$B$14*LOG10(1+E17) -> 2.9553922 | G17: =IFERROR(1/SUMPRODUCT((Sheep!$C$5:$C$23="Common")/INDEX('Rebirth Odds'!$C$9:$AB$27,0,$A17+1)),"-") -> 3.6257077 | H17: =IFERROR(1/SUMPRODUCT((Sheep!$C$5:$C$23="Uncommon")/INDEX('Rebirth Odds'!$C$9:$AB$27,0,$A17+1)),"-") -> 4.3814679 | I17: =IFERROR(1/SUMPRODUCT((Sheep!$C$5:$C$23="Rare")/INDEX('Rebirth Odds'!$C$9:$AB$27,0,$A17+1)),"-") -> 4.324056 | J17: =IFERROR(1/SUMPRODUCT((Sheep!$C$5:$C$23="Epic")/INDEX('Rebirth Odds'!$C$9:$AB$27,0,$A17+1)),"-") -> 4.8657611 | K17: =IFERROR(1/SUMPRODUCT((Sheep!$C$5:$C$23="Legendary")/INDEX('Rebirth Odds'!$C$9:$AB$27,0,$A17+1)),"-") -> 25.460417 | L17: =IFERROR(1/SUMPRODUCT((Sheep!$C$5:$C$23="Mythic")/INDEX('Rebirth Odds'!$C$9:$AB$27,0,$A17+1)),"-") -> 50.253601 | M17: =C17*Settings!$B$24*SUMPRODUCT(Sheep!$F$5:$F$23/INDEX('Rebirth Odds'!$C$9:$AB$27,0,$A17+1)) -> 3023.2517 | N17: =IF(ISNUMBER(B17),B17/M17,"-") -> 87892.284 | O17: =IF(ISNUMBER(N17),INDEX(Sheep!$A$5:$A$23,MATCH(P17,INDEX('Rebirth Odds'!$C$9:$AB$27,0,$A17+1),0)),"-") -> Obsidian Sheep | P17: =IF(ISNUMBER(N17),_xlfn.MAXIFS(INDEX('Rebirth Odds'!$C$9:$AB$27,0,$A17+1),INDEX('Rebirth Odds'!$C$9:$AB$27,0,$A17+1),"<="&N17),"-") -> 201.0144
... A31: 25 | B31: =IF(A31>=Settings!$B$15,"max",FLOOR(Settings!$B$16*Settings!$B$17^A31,1)) -> max | C31: =Settings!$B$18^A31 -> 25251.168 | D31: =IF(A31=0,0,FLOOR(Settings!$B$19*Settings!$B$20^(A31-1)*IF(MOD(A31,Settings!$B$21)=0,Settings!$B$22,1),1)) -> 746160 | E31: =SUM($D$6:D31) -> 1644029 | F31: =1+Settings!$B$14*LOG10(1+E31) -> 4.1079549 | G31: =IFERROR(1/SUMPRODUCT((Sheep!$C$5:$C$23="Common")/INDEX('Rebirth Odds'!$C$9:$AB$27,0,$A31+1)),"-") -> 6.6773092 | H31: =IFERROR(1/SUMPRODUCT((Sheep!$C$5:$C$23="Uncommon")/INDEX('Rebirth Odds'!$C$9:$AB$27,0,$A31+1)),"-") -> 5.8052081 | I31: =IFERROR(1/SUMPRODUCT((Sheep!$C$5:$C$23="Rare")/INDEX('Rebirth Odds'!$C$9:$AB$27,0,$A31+1)),"-") -> 4.1217242 | J31: =IFERROR(1/SUMPRODUCT((Sheep!$C$5:$C$23="Epic")/INDEX('Rebirth Odds'!$C$9:$AB$27,0,$A31+1)),"-") -> 3.3367822 | K31: =IFERROR(1/SUMPRODUCT((Sheep!$C$5:$C$23="Legendary")/INDEX('Rebirth Odds'!$C$9:$AB$27,0,$A31+1)),"-") -> 12.561227 | L31: =IFERROR(1/SUMPRODUCT((Sheep!$C$5:$C$23="Mythic")/INDEX('Rebirth Odds'!$C$9:$AB$27,0,$A31+1)),"-") -> 17.837057 | M31: =C31*Settings!$B$24*SUMPRODUCT(Sheep!$F$5:$F$23/INDEX('Rebirth Odds'!$C$9:$AB$27,0,$A31+1)) -> 1117056 | N31: =IF(ISNUMBER(B31),B31/M31,"-") -> - | O31: =IF(ISNUMBER(N31),INDEX(Sheep!$A$5:$A$23,MATCH(P31,INDEX('Rebirth Odds'!$C$9:$AB$27,0,$A31+1),0)),"-") -> - | P31: =IF(ISNUMBER(N31),_xlfn.MAXIFS(INDEX('Rebirth Odds'!$C$9:$AB$27,0,$A31+1),INDEX('Rebirth Odds'!$C$9:$AB$27,0,$A31+1),"<="&N31),"-") -> -
A33: Rarest sheep expected = the rarest sheep whose odds are no worse than the number of sheep you shear before affording the next rebirth (ignores upgrade spending and Luck earned mid-run).

Sheet Rebirth Odds
A1: Odds by Rebirth
A2: Each sheep's "1 in N" odds with the Luck a farm starts with after that many rebirths.
B5: Rebirths | C5: 0 | D5: 1 | E5: 2 | F5: 3 | G5: 4 | H5: 5 | I5: 6 | J5: 7 | K5: 8 | L5: 9 | M5: 10 | N5: 11 | O5: 12 | P5: 13 | Q5: 14 | R5: 15 | S5: 16 | T5: 17 | U5: 18 | V5: 19 | W5: 20 | X5: 21 | Y5: 22 | Z5: 23 | AA5: 24 | AB5: 25
B6: Starting Luck | C6: =INDEX(Rebirths!$E$6:$E$31,C$5+1) -> 0 | D6: =INDEX(Rebirths!$E$6:$E$31,D$5+1) -> 50 | E6: =INDEX(Rebirths!$E$6:$E$31,E$5+1) -> 122 | F6: =INDEX(Rebirths!$E$6:$E$31,F$5+1) -> 227 | G6: =INDEX(Rebirths!$E$6:$E$31,G$5+1) -> 379 | H6: =INDEX(Rebirths!$E$6:$E$31,H$5+1) -> 821 | I6: =INDEX(Rebirths!$E$6:$E$31,I$5+1) -> 1141 | J6: =INDEX(Rebirths!$E$6:$E$31,J$5+1) -> 1605 | ... AB6: =INDEX(Rebirths!$E$6:$E$31,AB$5+1) -> 1644029
B7: Luck factor | C7: =INDEX(Rebirths!$F$6:$F$31,C$5+1) -> 1 | D7: =INDEX(Rebirths!$F$6:$F$31,D$5+1) -> 1.8537851 | E7: =INDEX(Rebirths!$F$6:$F$31,E$5+1) -> 2.0449526 | F7: =INDEX(Rebirths!$F$6:$F$31,F$5+1) -> 2.1789674 | G7: =INDEX(Rebirths!$F$6:$F$31,G$5+1) -> 2.2898918 | H7: =INDEX(Rebirths!$F$6:$F$31,H$5+1) -> 2.4574359 | I7: =INDEX(Rebirths!$F$6:$F$31,I$5+1) -> 2.5288331 | J7: =INDEX(Rebirths!$F$6:$F$31,J$5+1) -> 2.6028728 | ... AB7: =INDEX(Rebirths!$F$6:$F$31,AB$5+1) -> 4.1079549
A8: Rarity | B8: Sheep | C8: Rebirth 0 | D8: Rebirth 1 | E8: Rebirth 2 | F8: Rebirth 3 | G8: Rebirth 4 | H8: Rebirth 5 | I8: Rebirth 6 | J8: Rebirth 7 | K8: Rebirth 8 | L8: Rebirth 9 | M8: Rebirth 10 | N8: Rebirth 11 | O8: Rebirth 12 | P8: Rebirth 13 | Q8: Rebirth 14 | R8: Rebirth 15 | S8: Rebirth 16 | T8: Rebirth 17 | U8: Rebirth 18 | V8: Rebirth 19 | W8: Rebirth 20 | X8: Rebirth 21 | Y8: Rebirth 22 | Z8: Rebirth 23 | AA8: Rebirth 24 | AB8: Rebirth 25
A9: =Sheep!C5 -> Common | B9: =Sheep!A5 -> Basic Sheep | C9: =SUMPRODUCT(Sheep!$H$5:$H$23*C$7^Sheep!$D$5:$D$23)/(Sheep!$H5*C$7^Sheep!$D5) -> 2.11058 | D9: =SUMPRODUCT(Sheep!$H$5:$H$23*D$7^Sheep!$D$5:$D$23)/(Sheep!$H5*D$7^Sheep!$D5) -> 3.0928696 | E9: =SUMPRODUCT(Sheep!$H$5:$H$23*E$7^Sheep!$D$5:$D$23)/(Sheep!$H5*E$7^Sheep!$D5) -> 3.3974811 | F9: =SUMPRODUCT(Sheep!$H$5:$H$23*F$7^Sheep!$D$5:$D$23)/(Sheep!$H5*F$7^Sheep!$D5) -> 3.6335212 | G9: =SUMPRODUCT(Sheep!$H$5:$H$23*G$7^Sheep!$D$5:$D$23)/(Sheep!$H5*G$7^Sheep!$D5) -> 3.8439577 | H9: =SUMPRODUCT(Sheep!$H$5:$H$23*H$7^Sheep!$D$5:$D$23)/(Sheep!$H5*H$7^Sheep!$D5) -> 4.1894612 | I9: =SUMPRODUCT(Sheep!$H$5:$H$23*I$7^Sheep!$D$5:$D$23)/(Sheep!$H5*I$7^Sheep!$D5) -> 4.3473817 | J9: =SUMPRODUCT(Sheep!$H$5:$H$23*J$7^Sheep!$D$5:$D$23)/(Sheep!$H5*J$7^Sheep!$D5) -> 4.5182312 | ... AB9: =SUMPRODUCT(Sheep!$H$5:$H$23*AB$7^Sheep!$D$5:$D$23)/(Sheep!$H5*AB$7^Sheep!$D5) -> 10.015964
A10: =Sheep!C6 -> Common | B10: =Sheep!A6 -> Grey Sheep | C10: =SUMPRODUCT(Sheep!$H$5:$H$23*C$7^Sheep!$D$5:$D$23)/(Sheep!$H6*C$7^Sheep!$D6) -> 4.22116 | D10: =SUMPRODUCT(Sheep!$H$5:$H$23*D$7^Sheep!$D$5:$D$23)/(Sheep!$H6*D$7^Sheep!$D6) -> 6.1857392 | E10: =SUMPRODUCT(Sheep!$H$5:$H$23*E$7^Sheep!$D$5:$D$23)/(Sheep!$H6*E$7^Sheep!$D6) -> 6.7949622 | F10: =SUMPRODUCT(Sheep!$H$5:$H$23*F$7^Sheep!$D$5:$D$23)/(Sheep!$H6*F$7^Sheep!$D6) -> 7.2670423 | G10: =SUMPRODUCT(Sheep!$H$5:$H$23*G$7^Sheep!$D$5:$D$23)/(Sheep!$H6*G$7^Sheep!$D6) -> 7.6879154 | H10: =SUMPRODUCT(Sheep!$H$5:$H$23*H$7^Sheep!$D$5:$D$23)/(Sheep!$H6*H$7^Sheep!$D6) -> 8.3789223 | I10: =SUMPRODUCT(Sheep!$H$5:$H$23*I$7^Sheep!$D$5:$D$23)/(Sheep!$H6*I$7^Sheep!$D6) -> 8.6947633 | J10: =SUMPRODUCT(Sheep!$H$5:$H$23*J$7^Sheep!$D$5:$D$23)/(Sheep!$H6*J$7^Sheep!$D6) -> 9.0364624 | ... AB10: =SUMPRODUCT(Sheep!$H$5:$H$23*AB$7^Sheep!$D$5:$D$23)/(Sheep!$H6*AB$7^Sheep!$D6) -> 20.031927
A11: =Sheep!C7 -> Uncommon | B11: =Sheep!A7 -> Brown Sheep | C11: =SUMPRODUCT(Sheep!$H$5:$H$23*C$7^Sheep!$D$5:$D$23)/(Sheep!$H7*C$7^Sheep!$D7) -> 7.0352667 | D11: =SUMPRODUCT(Sheep!$H$5:$H$23*D$7^Sheep!$D$5:$D$23)/(Sheep!$H7*D$7^Sheep!$D7) -> 5.5613595 | E11: =SUMPRODUCT(Sheep!$H$5:$H$23*E$7^Sheep!$D$5:$D$23)/(Sheep!$H7*E$7^Sheep!$D7) -> 5.537995 | F11: =SUMPRODUCT(Sheep!$H$5:$H$23*F$7^Sheep!$D$5:$D$23)/(Sheep!$H7*F$7^Sheep!$D7) -> 5.5584756 | G11: =SUMPRODUCT(Sheep!$H$5:$H$23*G$7^Sheep!$D$5:$D$23)/(Sheep!$H7*G$7^Sheep!$D7) -> 5.5955449 | H11: =SUMPRODUCT(Sheep!$H$5:$H$23*H$7^Sheep!$D$5:$D$23)/(Sheep!$H7*H$7^Sheep!$D7) -> 5.6826998 | I11: =SUMPRODUCT(Sheep!$H$5:$H$23*I$7^Sheep!$D$5:$D$23)/(Sheep!$H7*I$7^Sheep!$D7) -> 5.7304187 | J11: =SUMPRODUCT(Sheep!$H$5:$H$23*J$7^Sheep!$D$5:$D$23)/(Sheep!$H7*J$7^Sheep!$D7) -> 5.7862109 | ... AB11: =SUMPRODUCT(Sheep!$H$5:$H$23*AB$7^Sheep!$D$5:$D$23)/(Sheep!$H7*AB$7^Sheep!$D7) -> 8.1272913
A12: =Sheep!C8 -> Uncommon | B12: =Sheep!A8 -> Black Sheep | C12: =SUMPRODUCT(Sheep!$H$5:$H$23*C$7^Sheep!$D$5:$D$23)/(Sheep!$H8*C$7^Sheep!$D8) -> 17.588167 | D12: =SUMPRODUCT(Sheep!$H$5:$H$23*D$7^Sheep!$D$5:$D$23)/(Sheep!$H8*D$7^Sheep!$D8) -> 13.903399 | E12: =SUMPRODUCT(Sheep!$H$5:$H$23*E$7^Sheep!$D$5:$D$23)/(Sheep!$H8*E$7^Sheep!$D8) -> 13.844988 | F12: =SUMPRODUCT(Sheep!$H$5:$H$23*F$7^Sheep!$D$5:$D$23)/(Sheep!$H8*F$7^Sheep!$D8) -> 13.896189 | G12: =SUMPRODUCT(Sheep!$H$5:$H$23*G$7^Sheep!$D$5:$D$23)/(Sheep!$H8*G$7^Sheep!$D8) -> 13.988862 | H12: =SUMPRODUCT(Sheep!$H$5:$H$23*H$7^Sheep!$D$5:$D$23)/(Sheep!$H8*H$7^Sheep!$D8) -> 14.20675 | I12: =SUMPRODUCT(Sheep!$H$5:$H$23*I$7^Sheep!$D$5:$D$23)/(Sheep!$H8*I$7^Sheep!$D8) -> 14.326047 | J12: =SUMPRODUCT(Sheep!$H$5:$H$23*J$7^Sheep!$D$5:$D$23)/(Sheep!$H8*J$7^Sheep!$D8) -> 14.465527 | ... AB12: =SUMPRODUCT(Sheep!$H$5:$H$23*AB$7^Sheep!$D$5:$D$23)/(Sheep!$H8*AB$7^Sheep!$D8) -> 20.318228
A13: =Sheep!C9 -> Rare | B13: =Sheep!A9 -> Fluffy Sheep | C13: =SUMPRODUCT(Sheep!$H$5:$H$23*C$7^Sheep!$D$5:$D$23)/(Sheep!$H9*C$7^Sheep!$D9) -> 35.176333 | D13: =SUMPRODUCT(Sheep!$H$5:$H$23*D$7^Sheep!$D$5:$D$23)/(Sheep!$H9*D$7^Sheep!$D9) -> 15.000011 | E13: =SUMPRODUCT(Sheep!$H$5:$H$23*E$7^Sheep!$D$5:$D$23)/(Sheep!$H9*E$7^Sheep!$D9) -> 13.540644 | F13: =SUMPRODUCT(Sheep!$H$5:$H$23*F$7^Sheep!$D$5:$D$23)/(Sheep!$H9*F$7^Sheep!$D9) -> 12.754839 | G13: =SUMPRODUCT(Sheep!$H$5:$H$23*G$7^Sheep!$D$5:$D$23)/(Sheep!$H9*G$7^Sheep!$D9) -> 12.217924 | H13: =SUMPRODUCT(Sheep!$H$5:$H$23*H$7^Sheep!$D$5:$D$23)/(Sheep!$H9*H$7^Sheep!$D9) -> 11.562254 | I13: =SUMPRODUCT(Sheep!$H$5:$H$23*I$7^Sheep!$D$5:$D$23)/(Sheep!$H9*I$7^Sheep!$D9) -> 11.330164 | J13: =SUMPRODUCT(Sheep!$H$5:$H$23*J$7^Sheep!$D$5:$D$23)/(Sheep!$H9*J$7^Sheep!$D9) -> 11.115047 | ... AB13: =SUMPRODUCT(Sheep!$H$5:$H$23*AB$7^Sheep!$D$5:$D$23)/(Sheep!$H9*AB$7^Sheep!$D9) -> 9.892138
A14: =Sheep!C10 -> Rare | B14: =Sheep!A10 -> Cotton Candy Sheep | C14: =SUMPRODUCT(Sheep!$H$5:$H$23*C$7^Sheep!$D$5:$D$23)/(Sheep!$H10*C$7^Sheep!$D10) -> 47.967727 | D14: =SUMPRODUCT(Sheep!$H$5:$H$23*D$7^Sheep!$D$5:$D$23)/(Sheep!$H10*D$7^Sheep!$D10) -> 20.454561 | E14: =SUMPRODUCT(Sheep!$H$5:$H$23*E$7^Sheep!$D$5:$D$23)/(Sheep!$H10*E$7^Sheep!$D10) -> 18.464515 | F14: =SUMPRODUCT(Sheep!$H$5:$H$23*F$7^Sheep!$D$5:$D$23)/(Sheep!$H10*F$7^Sheep!$D10) -> 17.392962 | G14: =SUMPRODUCT(Sheep!$H$5:$H$23*G$7^Sheep!$D$5:$D$23)/(Sheep!$H10*G$7^Sheep!$D10) -> 16.660806 | H14: =SUMPRODUCT(Sheep!$H$5:$H$23*H$7^Sheep!$D$5:$D$23)/(Sheep!$H10*H$7^Sheep!$D10) -> 15.76671 | I14: =SUMPRODUCT(Sheep!$H$5:$H$23*I$7^Sheep!$D$5:$D$23)/(Sheep!$H10*I$7^Sheep!$D10) -> 15.450224 | J14: =SUMPRODUCT(Sheep!$H$5:$H$23*J$7^Sheep!$D$5:$D$23)/(Sheep!$H10*J$7^Sheep!$D10) -> 15.156883 | ... AB14: =SUMPRODUCT(Sheep!$H$5:$H$23*AB$7^Sheep!$D$5:$D$23)/(Sheep!$H10*AB$7^Sheep!$D10) -> 13.489279
